Workbook

Sheet Main
C3: PLEASE CHECK THE OTHER TABS AT THE BOTTOM! THIS IS ONLY THE FIRST TAB.
C4: IT IS RECOMMENDED THAT YOU ZOOM OUT TO SEE EVERYTHING BETTER.
C5: CLICK/TAP THE LINK INSIDE THAT BOX TO ACCESS THE TRAINER ORDER.
C6: REPORT MISTAKES IN THE #DOCUMENTATION-REPORTS CHANNEL ON OUR DISCORD SERVER.
C8: LEVEL CAPS
E10: Pre-Brock (15)
E12: Pre-Mt. Moon Archer (22)
E14: Pre-Misty (27)
E16: Pre-Lt. Surge (34)
E18: Pre-Erika (44)
E20: Pre-Game Corner Giovanni (47)
E22: Pre-Silph Co. Archer & Ariana (56)
E24: Pre-Giovanni Silph Co. (57)
E26: Pre-Sabrina (59)
E28: Pre-Koga (68)
E30: Pre-May (73)
E32: Pre-Blaine (76)
... E44: Post Game (100)
C46: HOW TO GET FOCUS SASH AND CHOICE ITEMS FROM QUESTS (MGM)
E48: Show a Pokémon with 125+ base stat in the respective stat (Chuck asks for a Pokémon with strong attack, show a mon with 125+ base attack like Terrakion).
C50: ABOUT THE SHEET
E52: All of the info in this sheet should be 100% accurate, because it was obtained via byte copying and using the Stat Scanner for EVs and IVs.
E54: Even if something looks VERY wrong, that's how it is in-game. Though, feel free to report text typos if you ever find those.
E56: Most of the opposing Pokémon's moves in this sheet are PP maxed. If the team has a Paldea Pokémon, it's likely that all the Pokémon in the team have PP maxed moves.
E58: Generally, if a Pokémon has Gyro Ball in its moveset or is part of a Trick Room team, you can safely assume 0 speed IVs.
E60: Rival's chosen starter determines what team he gets. If he has the Squirtle team, that means the player chose a Fire-type starter Pokémon.
E62: Status moves don't have a type icon near them, for the reader to identify damaging moves and their types better.
E64: In Minimal Grinding Mode, opponents don't have EVs. Except for one specific case which is the Ghost Marowak, having 252 HP EVs.
E66: After you become the Champion, every level scale (excluding Postgame trainers) will be two levels higher.
E68: All speed stats are determined based on the point when you're expected to battle with the trainer at that specific juncture in the game.

Sheet Trainer Order
C3: (!) CLICK ON TRAINER'S NAME | F3: LEVEL CAPS
C4: TO INSTANTLY GO TO PAGE!
C6: (OPTIONAL)
C7: =IMAGE("https://i.ibb.co/fXwks6z/Rival.png",4,150,150) | D7: RIVAL | F7: 15
D8: ROUTE 22
C11: =IMAGE("https://i.ibb.co/10ZXyNx/Brendan.png",4,150,150) | D11: BRENDAN | F11: 15
D12: VIRIDIAN FOREST
C15: =IMAGE("https://i.ibb.co/8sm893K/Lass.png",4,150,150) | D15: LASS ANNE | F15: 15
D16: VIRIDIAN FOREST
C19: (OPTIONAL)
C20: =IMAGE("https://i.ibb.co/26kF6WW/Ace-Trainer-F.png",4,150,150) | D20: ACE NELLE | F20: 15
D21: VIRIDIAN FOREST
C24: =IMAGE("https://i.ibb.co/NWQ5Qdk/Falkner.png",4,150,150) | D24: FALKNER | F24: 15
D25: PEWTER CITY
C28: =IMAGE("https://i.ibb.co/RBhc6sL/Brock.png",4,150,150) | D28: BROCK | F28: 15
D29: PEWTER CITY
C32: =IMAGE("https://i.ibb.co/zFMzgnB/Super-Nerd.png",4,150,150) | D32: SUPER NERD MIGUEL | F32: 22
D33: MT. MOON
C36: =IMAGE("https://i.ibb.co/xhnkr2Z/Archer.png",4,150,150) | D36: ARCHER | F36: 22
D37: MT. MOON
C40: =IMAGE("https://i.ibb.co/fXwks6z/Rival.png",4,150,150) | D40: RIVAL | F40: 27
D41: CERULEAN CITY
C44: =IMAGE("https://i.ibb.co/8D0GLzq/Bug-Catcher.png",4,150,150) | D44: CATCHER CALE | F44: 27
D45: NUGGET BRIDGE
C48: =IMAGE("https://i.ibb.co/8sm893K/Lass.png",4,150,150) | D48: LASS ALI | F48: 27
D49: NUGGET BRIDGE
C52: =IMAGE("https://i.ibb.co/6nGd7Gm/Youngster.png",4,150,150) | D52: YOUNGSTER TIMMY | F52: 27
D53: NUGGET BRIDGE
C56: =IMAGE("https://i.ibb.co/8sm893K/Lass.png",4,150,150) | D56: LASS RELI | F56: 27
D57: NUGGET BRIDGE
C60: =IMAGE("https://i.ibb.co/VxD4KtV/Camper.png",4,150,150) | D60: CAMPER ETHAN | F60: 27
D61: NUGGET BRIDGE
C64: =IMAGE("https://i.ibb.co/FzKmMqb/Grunt.png",4,150,150) | D64: GRUNT | F64: 27
D65: NUGGET BRIDGE
C68: (OPTIONAL)
C69: =IMAGE("https://i.ibb.co/Lrh0bjy/Bugsy.png",4,150,150) | D69: BUGSY | F69: 27
D70: ROUTE 25
C73: =IMAGE("https://i.ibb.co/hZTdVGf/Misty.png",4,150,150) | D73: MISTY | F73: 27
D74: CERULEAN CITY
C77: =IMAGE("https://i.ibb.co/FzKmMqb/Grunt.png",4,150,150) | D77: GRUNT | F77: 27
...

Sheet Kanto Leaders
C3: =IMAGE("https://i.ibb.co/v10Rh61/Brock.png") | E3: {=IFERROR(VLOOKUP(E4,Dex!$B$3:$G191,3,FALSE),"")} | J3: {=IFERROR(VLOOKUP(J4,Dex!$B$3:$G191,3,FALSE),"")} | O3: {=IFERROR(VLOOKUP(O4,Dex!$B$3:$G191,3,FALSE),"")} | T3: {=IFERROR(VLOOKUP(T4,Dex!$B$3:$G191,3,FALSE),"")}
C4: GYM LEADER BROCK | E4: Geodude-A | J4: Varoom | O4: Onix | T4: Archen
E5: 13 | J5: 13 | O5: 14 | T5: 12
F6: {=IFERROR(VLOOKUP(E4,Dex!$B$3:$H191,5,FALSE),"")} | G6: {=IFERROR(VLOOKUP(E4,Dex!$B$3:$H191,7,FALSE),"")} | K6: {=IFERROR(VLOOKUP(J4,Dex!$B$3:$H191,5,FALSE),"")} | L6: {=IFERROR(VLOOKUP(J4,Dex!$B$3:$H191,7,FALSE),"")} | P6: {=IFERROR(VLOOKUP(O4,Dex!$B$3:$H191,5,FALSE),"")} | Q6: {=IFERROR(VLOOKUP(O4,Dex!$B$3:$H191,7,FALSE),"")} | U6: {=IFERROR(VLOOKUP(T4,Dex!$B$3:$H191,5,FALSE),"")} | V6: {=IFERROR(VLOOKUP(T4,Dex!$B$3:$H191,7,FALSE),"")}
E8: Adamant | J8: Brave | O8: Bashful | T8: Jolly
E9: Sturdy | J9: Filter | O9: Sturdy | T9: Defeatist
E10: Custap Berry | H10: =IMAGE("https://raw.githubusercontent.com/msikma/pokesprite/master/items/berry/custap.png",3) | J10: Air Balloon | M10: =IMAGE("https://raw.githubusercontent.com/msikma/pokesprite/master/items/hold-item/air-balloon.png",3) | O10: Berry Juice | R10: =IMAGE("https://raw.githubusercontent.com/msikma/pokesprite/master/items/medicine/berry-juice.png",3) | T10: Berry Juice | W10: =IMAGE("https://raw.githubusercontent.com/msikma/pokesprite/master/items/medicine/berry-juice.png",3)
E11: Bulldoze | H11: =IMAGE("https://raw.githubusercontent.com/msikma/pokesprite/master/misc/types/gen8/ground.png",4,20,20) | J11: Gyro Ball | M11: =IMAGE("https://raw.githubusercontent.com/msikma/pokesprite/master/misc/types/gen8/steel.png",4,20,20) | O11: Rock Tomb | R11: =IMAGE("https://raw.githubusercontent.com/msikma/pokesprite/master/misc/types/gen8/rock.png",4,20,20) | T11: Pluck | W11: =IMAGE("https://raw.githubusercontent.com/msikma/pokesprite/master/misc/types/gen8/flying.png",4,20,20)
E12: Rock Tomb | H12: =IMAGE("https://raw.githubusercontent.com/msikma/pokesprite/master/misc/types/gen8/rock.png",4,20,20) | J12: Bulldoze | M12: =IMAGE("https://raw.githubusercontent.com/msikma/pokesprite/master/misc/types/gen8/ground.png",4,20,20) | O12: Bulldoze | R12: =IMAGE("https://raw.githubusercontent.com/msikma/pokesprite/master/misc/types/gen8/ground.png",4,20,20) | T12: Rock Tomb | W12: =IMAGE("https://raw.githubusercontent.com/msikma/pokesprite/master/misc/types/gen8/rock.png",4,20,20)
E13: Spark | H13: =IMAGE("https://raw.githubusercontent.com/msikma/pokesprite/master/misc/types/gen8/electric.png",4,20,20) | J13: Toxic | M13: =IMAGE("https://raw.githubusercontent.com/msikma/pokesprite/master/misc/types/gen8/poison.png",4,20,20) | O13: Sleep Talk | R13: =IMAGE("https://raw.githubusercontent.com/msikma/pokesprite/master/misc/types/gen8/normal.png",4,20,20) | T13: Bulldoze | W13: =IMAGE("https://raw.githubusercontent.com/msikma/pokesprite/master/misc/types/gen8/ground.png",4,20,20)
E14: Self-Destruct | H14: =IMAGE("https://raw.githubusercontent.com/msikma/pokesprite/master/misc/types/gen8/normal.png",4,20,20) | J14: Protect | M14: =IMAGE("https://raw.githubusercontent.com/msikma/pokesprite/master/misc/types/gen8/normal.png",4,20,20) | O14: - | T14: Facade | W14: =IMAGE("https://raw.githubusercontent.com/msikma/pokesprite/master/misc/types/gen8/normal.png",4,20,20)
E16: BASE STATS | H16: EVs | J16: BASE STATS | M16: EVs | O16: BASE STATS | R16: EVs | T16: BASE STATS | W16: EVs
E17: HP | F17: {=IFERROR(VLOOKUP(E4,Dex!$B$3:$N191,8,FALSE),"")} -> 40 | G17: {=IFERROR(VLOOKUP(F17,Dex!$P$22:$Q$276,2,FALSE),"")} | J17: HP | K17: {=IFERROR(VLOOKUP(J4,Dex!$B$3:$N191,8,FALSE),"")} -> 45 | L17: {=IFERROR(VLOOKUP(K17,Dex!$P$22:$Q$276,2,FALSE),"")} | O17: HP | P17: {=IFERROR(VLOOKUP(O4,Dex!$B$3:$N191,8,FALSE),"")} -> 50 | Q17: {=IFERROR(VLOOKUP(P17,Dex!$P$22:$Q$276,2,FALSE),"")} | T17: HP | U17: {=IFERROR(VLOOKUP(T4,Dex!$B$3:$N191,8,FALSE),"")} -> 55 | V17: {=IFERROR(VLOOKUP(U17,Dex!$P$22:$Q$276,2,FALSE),"")}
E18: ATK | F18: {=IFERROR(VLOOKUP(E4,Dex!$B$3:$N191,9,FALSE),"")} -> 80 | G18: {=IFERROR(VLOOKUP(F18,Dex!$P$22:$Q$276,2,FALSE),"")} | J18: ATK | K18: {=IFERROR(VLOOKUP(J4,Dex!$B$3:$N191,9,FALSE),"")} -> 70 | L18: {=IFERROR(VLOOKUP(K18,Dex!$P$22:$Q$276,2,FALSE),"")} | O18: ATK | P18: {=IFERROR(VLOOKUP(O4,Dex!$B$3:$N191,9,FALSE),"")} -> 60 | Q18: {=IFERROR(VLOOKUP(P18,Dex!$P$22:$Q$276,2,FALSE),"")} | T18: ATK | U18: {=IFERROR(VLOOKUP(T4,Dex!$B$3:$N191,9,FALSE),"")} -> 112 | V18: {=IFERROR(VLOOKUP(U18,Dex!$P$22:$Q$276,2,FALSE),"")}
E19: DEF | F19: {=IFERROR(VLOOKUP(E4,Dex!$B$3:$N191,10,FALSE),"")} -> 100 | G19: {=IFERROR(VLOOKUP(F19,Dex!$P$22:$Q$276,2,FALSE),"")} | J19: DEF | K19: {=IFERROR(VLOOKUP(J4,Dex!$B$3:$N191,10,FALSE),"")} -> 63 | L19: {=IFERROR(VLOOKUP(K19,Dex!$P$22:$Q$276,2,FALSE),"")} | O19: DEF | P19: {=IFERROR(VLOOKUP(O4,Dex!$B$3:$N191,10,FALSE),"")} -> 150 | Q19: {=IFERROR(VLOOKUP(P19,Dex!$P$22:$Q$276,2,FALSE),"")} | T19: DEF | U19: {=IFERROR(VLOOKUP(T4,Dex!$B$3:$N191,10,FALSE),"")} -> 45 | V19: {=IFERROR(VLOOKUP(U19,Dex!$P$22:$Q$276,2,FALSE),"")}
E20: SPA | F20: {=IFERROR(VLOOKUP(E4,Dex!$B$3:$N191,11,FALSE),"")} -> 30 | G20: {=IFERROR(VLOOKUP(F20,Dex!$P$22:$Q$276,2,FALSE),"")} | J20: SPA | K20: {=IFERROR(VLOOKUP(J4,Dex!$B$3:$N191,11,FALSE),"")} -> 30 | L20: {=IFERROR(VLOOKUP(K20,Dex!$P$22:$Q$276,2,FALSE),"")} | O20: SPA | P20: {=IFERROR(VLOOKUP(O4,Dex!$B$3:$N191,11,FALSE),"")} -> 30 | Q20: {=IFERROR(VLOOKUP(P20,Dex!$P$22:$Q$276,2,FALSE),"")} | T20: SPA | U20: {=IFERROR(VLOOKUP(T4,Dex!$B$3:$N191,11,FALSE),"")} -> 74 | V20: {=IFERROR(VLOOKUP(U20,Dex!$P$22:$Q$276,2,FALSE),"")}
E21: SPD | F21: {=IFERROR(VLOOKUP(E4,Dex!$B$3:$N191,12,FALSE),"")} -> 30 | G21: {=IFERROR(VLOOKUP(F21,Dex!$P$22:$Q$276,2,FALSE),"")} | J21: SPD | K21: {=IFERROR(VLOOKUP(J4,Dex!$B$3:$N191,12,FALSE),"")} -> 45 | L21: {=IFERROR(VLOOKUP(K21,Dex!$P$22:$Q$276,2,FALSE),"")} | O21: SPD | P21: {=IFERROR(VLOOKUP(O4,Dex!$B$3:$N191,12,FALSE),"")} -> 45 | Q21: {=IFERROR(VLOOKUP(P21,Dex!$P$22:$Q$276,2,FALSE),"")} | T21: SPD | U21: {=IFERROR(VLOOKUP(T4,Dex!$B$3:$N191,12,FALSE),"")} -> 45 | V21: {=IFERROR(VLOOKUP(U21,Dex!$P$22:$Q$276,2,FALSE),"")}
E22: SPE | F22: {=IFERROR(VLOOKUP(E4,Dex!$B$3:$N191,13,FALSE),"")} -> 20 | G22: {=IFERROR(VLOOKUP(F22,Dex!$P$22:$Q$276,2,FALSE),"")} | J22: SPE | K22: {=IFERROR(VLOOKUP(J4,Dex!$B$3:$N191,13,FALSE),"")} -> 47 | L22: {=IFERROR(VLOOKUP(K22,Dex!$P$22:$Q$276,2,FALSE),"")} | O22: SPE | P22: {=IFERROR(VLOOKUP(O4,Dex!$B$3:$N191,13,FALSE),"")} -> 65 | Q22: {=IFERROR(VLOOKUP(P22,Dex!$P$22:$Q$276,2,FALSE),"")} | T22: SPE | U22: {=IFERROR(VLOOKUP(T4,Dex!$B$3:$N191,13,FALSE),"")} -> 70 | V22: {=IFERROR(VLOOKUP(U22,Dex!$P$22:$Q$276,2,FALSE),"")}
E23: SPEED STAT: | H23: 14 | J23: SPEED STAT: | M23: 15 | O23: SPEED STAT: | R23: 27 | T23: SPEED STAT: | W23: 27
C26: =IMAGE("https://i.ibb.co/mh2zYn4/Misty.png") | E26: {=IFERROR(VLOOKUP(E27,Dex!$B$3:$G191,3,FALSE),"")} | J26: {=IFERROR(VLOOKUP(J27,Dex!$B$3:$G191,3,FALSE),"")} | O26: {=IFERROR(VLOOKUP(O27,Dex!$B$3:$G191,3,FALSE),"")} | T26: {=IFERROR(VLOOKUP(T27,Dex!$B$3:$G191,3,FALSE),"")}
C27: GYM LEADER MISTY | E27: Frogadier | J27: Floatzel | O27: Starmie | T27: Clodsire
E28: 25 | J28: 25 | O28: 27 | T28: 26
F29: {=IFERROR(VLOOKUP(E27,Dex!$B$3:$H191,5,FALSE),"")} | K29: {=IFERROR(VLOOKUP(J27,Dex!$B$3:$H191,5,FALSE),"")} | P29: {=IFERROR(VLOOKUP(O27,Dex!$B$3:$H191,5,FALSE),"")} | Q29: {=IFERROR(VLOOKUP(O27,Dex!$B$3:$H191,7,FALSE),"")} | U29: {=IFERROR(VLOOKUP(T27,Dex!$B$3:$H191,5,FALSE),"")} | V29: {=IFERROR(VLOOKUP(T27,Dex!$B$3:$H191,7,FALSE),"")}
E31: Lonely | J31: Timid | O31: Timid | T31: Bold
E32: Protean | J32: Technician | O32: Analytic | T32: Water Absorb
E33: Eviolite | H33: =IMAGE("https://raw.githubusercontent.com/msikma/pokesprite/master/items/hold-item/eviolite.png",3) | J33: Mystic Water | M33: =IMAGE("https://raw.githubusercontent.com/msikma/pokesprite/master/items/hold-item/mystic-water.png",3) | O33: Sitrus Berry | R33: =IMAGE("https://raw.githubusercontent.com/msikma/pokesprite/master/items/berry/sitrus.png",3) | T33: Iapapa Berry | W33: =IMAGE("https://raw.githubusercontent.com/msikma/pokesprite/master/items/berry/iapapa.png",3)
E34: Ice Punch | H34: =IMAGE("https://raw.githubusercontent.com/msikma/pokesprite/master/misc/types/gen8/ice.png",4,20,20) | J34: Water Pulse | M34: =IMAGE("https://raw.githubusercontent.com/msikma/pokesprite/master/misc/types/gen8/water.png",4,20,20) | O34: Psyshock | R34: =IMAGE("https://raw.githubusercontent.com/msikma/pokesprite/master/misc/types/gen8/psychic.png",4,20,20) | T34: Poison Jab | W34: =IMAGE("https://raw.githubusercontent.com/msikma/pokesprite/master/misc/types/gen8/poison.png",4,20,20)
E35: Rock Tomb | H35: =IMAGE("https://raw.githubusercontent.com/msikma/pokesprite/master/misc/types/gen8/rock.png",4,20,20) | J35: Flip Turn | M35: =IMAGE("https://raw.githubusercontent.com/msikma/pokesprite/master/misc/types/gen8/water.png",4,20,20) | O35: Water Pulse | R35: =IMAGE("https://raw.githubusercontent.com/msikma/pokesprite/master/misc/types/gen8/water.png",4,20,20) | T35: Bulldoze | W35: =IMAGE("https://raw.githubusercontent.com/msikma/pokesprite/master/misc/types/gen8/ground.png",4,20,20)
E36: Flip Turn | H36: =IMAGE("https://raw.githubusercontent.com/msikma/pokesprite/master/misc/types/gen8/water.png",4,20,20) | J36: Icy Wind | M36: =IMAGE("https://raw.githubusercontent.com/msikma/pokesprite/master/misc/types/gen8/ice.png",4,20,20) | O36: Recover | R36: =IMAGE("https://raw.githubusercontent.com/msikma/pokesprite/master/misc/types/gen8/normal.png",4,20,20) | T36: Rock Tomb | W36: =IMAGE("https://raw.githubusercontent.com/msikma/pokesprite/master/misc/types/gen8/rock.png",4,20,20)
E37: Grass Knot | H37: =IMAGE("https://raw.githubusercontent.com/msikma/pokesprite/master/misc/types/gen8/grass.png",4,20,20) | J37: HP Grass | M37: =IMAGE("https://raw.githubusercontent.com/msikma/pokesprite/master/misc/types/gen8/grass.png",4,20,20) | O37: Aurora Beam | R37: =IMAGE("https://raw.githubusercontent.com/msikma/pokesprite/master/misc/types/gen8/ice.png",4,20,20) | T37: Recover | W37: =IMAGE("https://raw.githubusercontent.com/msikma/pokesprite/master/misc/types/gen8/normal.png",4,20,20)
E39: BASE STATS | H39: EVs | J39: BASE STATS | M39: EVs | O39: BASE STATS | R39: EVs | T39: BASE STATS | W39: EVs
E40: HP | F40: {=IFERROR(VLOOKUP(E27,Dex!$B$3:$N191,8,FALSE),"")} -> 54 | G40: {=IFERROR(VLOOKUP(F40,Dex!$P$22:$Q$276,2,FALSE),"")} | H40: 100 | J40: HP | K40: {=IFERROR(VLOOKUP(J27,Dex!$B$3:$N191,8,FALSE),"")} -> 85 | L40: {=IFERROR(VLOOKUP(K40,Dex!$P$22:$Q$276,2,FALSE),"")} | O40: HP | P40: {=IFERROR(VLOOKUP(O27,Dex!$B$3:$N191,8,FALSE),"")} -> 60 | Q40: {=IFERROR(VLOOKUP(P40,Dex!$P$22:$Q$276,2,FALSE),"")} | T40: HP | U40: {=IFERROR(VLOOKUP(T27,Dex!$B$3:$N191,8,FALSE),"")} -> 130 | V40: {=IFERROR(VLOOKUP(U40,Dex!$P$22:$Q$276,2,FALSE),"")}
E41: ATK | F41: {=IFERROR(VLOOKUP(E27,Dex!$B$3:$N191,9,FALSE),"")} -> 63 | G41: {=IFERROR(VLOOKUP(F41,Dex!$P$22:$Q$276,2,FALSE),"")} | H41: 40 | J41: ATK | K41: {=IFERROR(VLOOKUP(J27,Dex!$B$3:$N191,9,FALSE),"")} -> 90 | L41: {=IFERROR(VLOOKUP(K41,Dex!$P$22:$Q$276,2,FALSE),"")} | O41: ATK | P41: {=IFERROR(VLOOKUP(O27,Dex!$B$3:$N191,9,FALSE),"")} -> 75 | Q41: {=IFERROR(VLOOKUP(P41,Dex!$P$22:$Q$276,2,FALSE),"")} | T41: ATK | U41: {=IFERROR(VLOOKUP(T27,Dex!$B$3:$N191,9,FALSE),"")} -> 75 | V41: {=IFERROR(VLOOKUP(U41,Dex!$P$22:$Q$276,2,FALSE),"")}
E42: DEF | F42: {=IFERROR(VLOOKUP(E27,Dex!$B$3:$N191,10,FALSE),"")} -> 52 | G42: {=IFERROR(VLOOKUP(F42,Dex!$P$22:$Q$276,2,FALSE),"")} | J42: DEF | K42: {=IFERROR(VLOOKUP(J27,Dex!$B$3:$N191,10,FALSE),"")} -> 55 | L42: {=IFERROR(VLOOKUP(K42,Dex!$P$22:$Q$276,2,FALSE),"")} | O42: DEF | P42: {=IFERROR(VLOOKUP(O27,Dex!$B$3:$N191,10,FALSE),"")} -> 85 | Q42: {=IFERROR(VLOOKUP(P42,Dex!$P$22:$Q$276,2,FALSE),"")} | T42: DEF | U42: {=IFERROR(VLOOKUP(T27,Dex!$B$3:$N191,10,FALSE),"")} -> 60 | V42: {=IFERROR(VLOOKUP(U42,Dex!$P$22:$Q$276,2,FALSE),"")}
E43: SPA | F43: {=IFERROR(VLOOKUP(E27,Dex!$B$3:$N191,11,FALSE),"")} -> 83 | G43: {=IFERROR(VLOOKUP(F43,Dex!$P$22:$Q$276,2,FALSE),"")} | H43: 40 | J43: SPA | K43: {=IFERROR(VLOOKUP(J27,Dex!$B$3:$N191,11,FALSE),"")} -> 95 | L43: {=IFERROR(VLOOKUP(K43,Dex!$P$22:$Q$276,2,FALSE),"")} | O43: SPA | P43: {=IFERROR(VLOOKUP(O27,Dex!$B$3:$N191,11,FALSE),"")} -> 100 | Q43: {=IFERROR(VLOOKUP(P43,Dex!$P$22:$Q$276,2,FALSE),"")} | T43: SPA | U43: {=IFERROR(VLOOKUP(T27,Dex!$B$3:$N191,11,FALSE),"")} -> 45 | V43: {=IFERROR(VLOOKUP(U43,Dex!$P$22:$Q$276,2,FALSE),"")}
E44: SPD | F44: {=IFERROR(VLOOKUP(E27,Dex!$B$3:$N191,12,FALSE),"")} -> 56 | G44: {=IFERROR(VLOOKUP(F44,Dex!$P$22:$Q$276,2,FALSE),"")} | J44: SPD | K44: {=IFERROR(VLOOKUP(J27,Dex!$B$3:$N191,12,FALSE),"")} -> 50 | L44: {=IFERROR(VLOOKUP(K44,Dex!$P$22:$Q$276,2,FALSE),"")} | O44: SPD | P44: {=IFERROR(VLOOKUP(O27,Dex!$B$3:$N191,12,FALSE),"")} -> 85 | Q44: {=IFERROR(VLOOKUP(P44,Dex!$P$22:$Q$276,2,FALSE),"")} | T44: SPD | U44: {=IFERROR(VLOOKUP(T27,Dex!$B$3:$N191,12,FALSE),"")} -> 100 | V44: {=IFERROR(VLOOKUP(U44,Dex!$P$22:$Q$276,2,FALSE),"")}
E45: SPE | F45: {=IFERROR(VLOOKUP(E27,Dex!$B$3:$N191,13,FALSE),"")} -> 97 | G45: {=IFERROR(VLOOKUP(F45,Dex!$P$22:$Q$276,2,FALSE),"")} | J45: SPE | K45: {=IFERROR(VLOOKUP(J27,Dex!$B$3:$N191,13,FALSE),"")} -> 115 | L45: {=IFERROR(VLOOKUP(K45,Dex!$P$22:$Q$276,2,FALSE),"")} | O45: SPE | P45: {=IFERROR(VLOOKUP(O27,Dex!$B$3:$N191,13,FALSE),"")} -> 115 | Q45: {=IFERROR(VLOOKUP(P45,Dex!$P$22:$Q$276,2,FALSE),"")} | T45: SPE | U45: {=IFERROR(VLOOKUP(T27,Dex!$B$3:$N191,13,FALSE),"")} -> 20 | V45: {=IFERROR(VLOOKUP(U45,Dex!$P$22:$Q$276,2,FALSE),"")}
E46: SPEED STAT: | H46: 61 | J46: SPEED STAT: | M46: 77 | O46: SPEED STAT: | R46: 82 | T46: SPEED STAT: | W46: 23
C49: =IMAGE("https://i.ibb.co/w6kjj5K/Surge.png") | E49: {=IFERROR(VLOOKUP(E50,Dex!$B$3:$G191,3,FALSE),"")} | J49: {=IFERROR(VLOOKUP(J50,Dex!$B$3:$G191,3,FALSE),"")} | O49: {=IFERROR(VLOOKUP(O50,Dex!$B$3:$G191,3,FALSE),"")} | T49: {=IFERROR(VLOOKUP(T50,Dex!$B$3:$G191,3,FALSE),"")} | Y49: {=IFERROR(VLOOKUP(Y50,Dex!$B$3:$G191,3,FALSE),"")}
C50: GYM LEADER LT. SURGE | E50: Pincurchin | J50: Vikavolt | O50: Bellibolt | T50: Pawmot | Y50: Manectric-Mega
...

Sheet Kanto Rematch
E3: BATTLE EFFECT: PERMANENT SANDSTORM
C4: =IMAGE("https://i.ibb.co/v10Rh61/Brock.png") | E4: {=IFERROR(VLOOKUP(E5,Dex!$B$3:$G102,3,FALSE),"")} | J4: {=IFERROR(VLOOKUP(J5,Dex!$B$3:$G102,3,FALSE),"")} | O4: {=IFERROR(VLOOKUP(O5,Dex!$B$3:$G102,3,FALSE),"")} | T4: {=IFERROR(VLOOKUP(T5,Dex!$B$3:$G102,3,FALSE),"")} | Y4: {=IFERROR(VLOOKUP(Y5,Dex!$B$3:$G102,3,FALSE),"")} | AD4: {=IFERROR(VLOOKUP(AD5,Dex!$B$3:$G102,3,FALSE),"")}
C5: GYM LEADER BROCK | E5: Great Tusk | J5: Omastar | O5: Ursaluna-BM | T5: Tyranitar | Y5: Arcanine-H | AD5: Aerodactyl-Mega
E6: Highest Lv -2 | J6: Highest Lv -2 | O6: Highest Lv -2 | T6: Highest Lv -2 | Y6: Highest Lv -2 | AD6: Highest Lv -2
F7: {=IFERROR(VLOOKUP(E5,Dex!$B$3:$H102,5,FALSE),"")} | G7: {=IFERROR(VLOOKUP(E5,Dex!$B$3:$H102,7,FALSE),"")} | K7: {=IFERROR(VLOOKUP(J5,Dex!$B$3:$H102,5,FALSE),"")} | L7: {=IFERROR(VLOOKUP(J5,Dex!$B$3:$H102,7,FALSE),"")} | P7: {=IFERROR(VLOOKUP(O5,Dex!$B$3:$H102,5,FALSE),"")} | Q7: {=IFERROR(VLOOKUP(O5,Dex!$B$3:$H102,7,FALSE),"")} | U7: {=IFERROR(VLOOKUP(T5,Dex!$B$3:$H102,5,FALSE),"")} | V7: {=IFERROR(VLOOKUP(T5,Dex!$B$3:$H102,7,FALSE),"")} | Z7: {=IFERROR(VLOOKUP(Y5,Dex!$B$3:$H102,5,FALSE),"")} | AA7: {=IFERROR(VLOOKUP(Y5,Dex!$B$3:$H102,7,FALSE),"")} | AE7: {=IFERROR(VLOOKUP(AD5,Dex!$B$3:$H102,5,FALSE),"")} | AF7: {=IFERROR(VLOOKUP(AD5,Dex!$B$3:$H102,7,FALSE),"")}
E9: Jolly | J9: Timid | O9: Modest | T9: Jolly | Y9: Jolly | AD9: Jolly
E10: Protosynthesis | J10: Weak Armor | O10: Scrappy | T10: Sand Stream | Y10: Rock Head | AD10: Pressure Tough Claws
E11: Booster Energy | H11: =IMAGE("https://i.ibb.co/SK50ng3/booster.png",4,22,22) | J11: Power Herb | M11: =IMAGE("https://raw.githubusercontent.com/msikma/pokesprite/master/items/hold-item/power-herb.png",3) | O11: Leftovers | R11: =IMAGE("https://raw.githubusercontent.com/msikma/pokesprite/master/items/hold-item/leftovers.png",3) | T11: Weakness Pol. | W11: =IMAGE("https://raw.githubusercontent.com/msikma/pokesprite/master/items/hold-item/weakness-policy.png",3) | Y11: Focus Sash | AB11: =IMAGE("https://raw.githubusercontent.com/msikma/pokesprite/master/items/hold-item/focus-sash.png",3) | AD11: Aerodactylite | AG11: =IMAGE("https://raw.githubusercontent.com/msikma/pokesprite/master/items/mega-stone/aerodactylite.png",3)
E12: Stealth Rock | H12: =IMAGE("https://raw.githubusercontent.com/msikma/pokesprite/master/misc/types/gen8/rock.png",4,20,20) | J12: Shell Smash | M12: =IMAGE("https://raw.githubusercontent.com/msikma/pokesprite/master/misc/types/gen8/normal.png",4,20,20) | O12: Earth Power | R12: =IMAGE("https://raw.githubusercontent.com/msikma/pokesprite/master/misc/types/gen8/ground.png",4,20,20) | T12: Dragon Dance | W12: =IMAGE("https://raw.githubusercontent.com/msikma/pokesprite/master/misc/types/gen8/dragon.png",4,20,20) | Y12: Flare Blitz | AB12: =IMAGE("https://raw.githubusercontent.com/msikma/pokesprite/master/misc/types/gen8/fire.png",4,20,20) | AD12: Dragon Dance | AG12: =IMAGE("https://raw.githubusercontent.com/msikma/pokesprite/master/misc/types/gen8/dragon.png",4,20,20)
E13: Close Combat | H13: =IMAGE("https://raw.githubusercontent.com/msikma/pokesprite/master/misc/types/gen8/fighting.png",4,20,20) | J13: Meteor Beam | M13: =IMAGE("https://raw.githubusercontent.com/msikma/pokesprite/master/misc/types/gen8/rock.png",4,20,20) | O13: Blood Moon | R13: =IMAGE("https://raw.githubusercontent.com/msikma/pokesprite/master/misc/types/gen8/normal.png",4,20,20) | T13: Stone Edge | W13: =IMAGE("https://raw.githubusercontent.com/msikma/pokesprite/master/misc/types/gen8/rock.png",4,20,20) | Y13: Head Smash | AB13: =IMAGE("https://raw.githubusercontent.com/msikma/pokesprite/master/misc/types/gen8/rock.png",4,20,20) | AD13: Stone Edge | AG13: =IMAGE("https://raw.githubusercontent.com/msikma/pokesprite/master/misc/types/gen8/rock.png",4,20,20)
E14: Headlon. Rush | H14: =IMAGE("https://raw.githubusercontent.com/msikma/pokesprite/master/misc/types/gen8/ground.png",4,20,20) | J14: Surf | M14: =IMAGE("https://raw.githubusercontent.com/msikma/pokesprite/master/misc/types/gen8/water.png",4,20,20) | O14: Vacuum Wave | R14: =IMAGE("https://raw.githubusercontent.com/msikma/pokesprite/master/misc/types/gen8/fighting.png",4,20,20) | T14: Fire Punch | W14: =IMAGE("https://raw.githubusercontent.com/msikma/pokesprite/master/misc/types/gen8/fire.png",4,20,20) | Y14: Wild Charge | AB14: =IMAGE("https://raw.githubusercontent.com/msikma/pokesprite/master/misc/types/gen8/electric.png",4,20,20) | AD14: Earthquake | AG14: =IMAGE("https://raw.githubusercontent.com/msikma/pokesprite/master/misc/types/gen8/ground.png",4,20,20)
E15: Knock Off | H15: =IMAGE("https://raw.githubusercontent.com/msikma/pokesprite/master/misc/types/gen8/dark.png",4,20,20) | J15: Ice Beam | M15: =IMAGE("https://raw.githubusercontent.com/msikma/pokesprite/master/misc/types/gen8/ice.png",4,20,20) | O15: Hyper Voice | R15: =IMAGE("https://raw.githubusercontent.com/msikma/pokesprite/master/misc/types/gen8/normal.png",4,20,20) | T15: Knock Off | W15: =IMAGE("https://raw.githubusercontent.com/msikma/pokesprite/master/misc/types/gen8/dark.png",4,20,20) | Y15: Extreme Speed | AB15: =IMAGE("https://raw.githubusercontent.com/msikma/pokesprite/master/misc/types/gen8/normal.png",4,20,20) | AD15: Dual Wingbeat | AG15: =IMAGE("https://raw.githubusercontent.com/msikma/pokesprite/master/misc/types/gen8/flying.png",4,20,20)
E17: BASE STATS | H17: EVs | J17: BASE STATS | M17: EVs | O17: BASE STATS | R17: EVs | T17: BASE STATS | W17: EVs | Y17: BASE STATS | AB17: EVs | AD17: BASE STATS | AG17: EVs
E18: HP | F18: {=IFERROR(VLOOKUP(E5,Dex!$B$3:$N102,8,FALSE),"")} -> 115 | G18: {=IFERROR(VLOOKUP(F18,Dex!$P$22:$Q$276,2,FALSE),"")} | J18: HP | K18: {=IFERROR(VLOOKUP(J5,Dex!$B$3:$N102,8,FALSE),"")} -> 70 | L18: {=IFERROR(VLOOKUP(K18,Dex!$P$22:$Q$276,2,FALSE),"")} | O18: HP | P18: {=IFERROR(VLOOKUP(O5,Dex!$B$3:$N102,8,FALSE),"")} -> 113 | Q18: {=IFERROR(VLOOKUP(P18,Dex!$P$22:$Q$276,2,FALSE),"")} | R18: 252 | T18: HP | U18: {=IFERROR(VLOOKUP(T5,Dex!$B$3:$N102,8,FALSE),"")} -> 100 | V18: {=IFERROR(VLOOKUP(U18,Dex!$P$22:$Q$276,2,FALSE),"")} | Y18: HP | Z18: {=IFERROR(VLOOKUP(Y5,Dex!$B$3:$N102,8,FALSE),"")} -> 95 | AA18: {=IFERROR(VLOOKUP(Z18,Dex!$P$22:$Q$276,2,FALSE),"")} | AD18: HP | AE18: {=IFERROR(VLOOKUP(AD5,Dex!$B$3:$N102,8,FALSE),"")} -> 80 | AF18: {=IFERROR(VLOOKUP(AE18,Dex!$P$22:$Q$276,2,FALSE),"")}
E19: ATK | F19: {=IFERROR(VLOOKUP(E5,Dex!$B$3:$N102,9,FALSE),"")} -> 131 | G19: {=IFERROR(VLOOKUP(F19,Dex!$P$22:$Q$276,2,FALSE),"")} | H19: 252 | J19: ATK | K19: {=IFERROR(VLOOKUP(J5,Dex!$B$3:$N102,9,FALSE),"")} -> 60 | L19: {=IFERROR(VLOOKUP(K19,Dex!$P$22:$Q$276,2,FALSE),"")} | O19: ATK | P19: {=IFERROR(VLOOKUP(O5,Dex!$B$3:$N102,9,FALSE),"")} -> 70 | Q19: {=IFERROR(VLOOKUP(P19,Dex!$P$22:$Q$276,2,FALSE),"")} | T19: ATK | U19: {=IFERROR(VLOOKUP(T5,Dex!$B$3:$N102,9,FALSE),"")} -> 134 | V19: {=IFERROR(VLOOKUP(U19,Dex!$P$22:$Q$276,2,FALSE),"")} | W19: 252 | Y19: ATK | Z19: {=IFERROR(VLOOKUP(Y5,Dex!$B$3:$N102,9,FALSE),"")} -> 125 | AA19: {=IFERROR(VLOOKUP(Z19,Dex!$P$22:$Q$276,2,FALSE),"")} | AB19: 252 | AD19: ATK | AE19: {=IFERROR(VLOOKUP(AD5,Dex!$B$3:$N102,9,FALSE),"")} -> 135 | AF19: {=IFERROR(VLOOKUP(AE19,Dex!$P$22:$Q$276,2,FALSE),"")} | AG19: 252
E20: DEF | F20: {=IFERROR(VLOOKUP(E5,Dex!$B$3:$N102,10,FALSE),"")} -> 131 | G20: {=IFERROR(VLOOKUP(F20,Dex!$P$22:$Q$276,2,FALSE),"")} | J20: DEF | K20: {=IFERROR(VLOOKUP(J5,Dex!$B$3:$N102,10,FALSE),"")} -> 125 | L20: {=IFERROR(VLOOKUP(K20,Dex!$P$22:$Q$276,2,FALSE),"")} | O20: DEF | P20: {=IFERROR(VLOOKUP(O5,Dex!$B$3:$N102,10,FALSE),"")} -> 120 | Q20: {=IFERROR(VLOOKUP(P20,Dex!$P$22:$Q$276,2,FALSE),"")} | T20: DEF | U20: {=IFERROR(VLOOKUP(T5,Dex!$B$3:$N102,10,FALSE),"")} -> 110 | V20: {=IFERROR(VLOOKUP(U20,Dex!$P$22:$Q$276,2,FALSE),"")} | Y20: DEF | Z20: {=IFERROR(VLOOKUP(Y5,Dex!$B$3:$N102,10,FALSE),"")} -> 80 | AA20: {=IFERROR(VLOOKUP(Z20,Dex!$P$22:$Q$276,2,FALSE),"")} | AD20: DEF | AE20: {=IFERROR(VLOOKUP(AD5,Dex!$B$3:$N102,10,FALSE),"")} -> 85 | AF20: {=IFERROR(VLOOKUP(AE20,Dex!$P$22:$Q$276,2,FALSE),"")}
E21: SPA | F21: {=IFERROR(VLOOKUP(E5,Dex!$B$3:$N102,11,FALSE),"")} -> 53 | G21: {=IFERROR(VLOOKUP(F21,Dex!$P$22:$Q$276,2,FALSE),"")} | J21: SPA | K21: {=IFERROR(VLOOKUP(J5,Dex!$B$3:$N102,11,FALSE),"")} -> 115 | L21: {=IFERROR(VLOOKUP(K21,Dex!$P$22:$Q$276,2,FALSE),"")} | M21: 252 | O21: SPA | P21: {=IFERROR(VLOOKUP(O5,Dex!$B$3:$N102,11,FALSE),"")} -> 135 | Q21: {=IFERROR(VLOOKUP(P21,Dex!$P$22:$Q$276,2,FALSE),"")} | R21: 252 | T21: SPA | U21: {=IFERROR(VLOOKUP(T5,Dex!$B$3:$N102,11,FALSE),"")} -> 95 | V21: {=IFERROR(VLOOKUP(U21,Dex!$P$22:$Q$276,2,FALSE),"")} | Y21: SPA | Z21: {=IFERROR(VLOOKUP(Y5,Dex!$B$3:$N102,11,FALSE),"")} -> 85 | AA21: {=IFERROR(VLOOKUP(Z21,Dex!$P$22:$Q$276,2,FALSE),"")} | AD21: SPA | AE21: {=IFERROR(VLOOKUP(AD5,Dex!$B$3:$N102,11,FALSE),"")} -> 70 | AF21: {=IFERROR(VLOOKUP(AE21,Dex!$P$22:$Q$276,2,FALSE),"")}
E22: SPD | F22: {=IFERROR(VLOOKUP(E5,Dex!$B$3:$N102,12,FALSE),"")} -> 53 | G22: {=IFERROR(VLOOKUP(F22,Dex!$P$22:$Q$276,2,FALSE),"")} | H22: 4 | J22: SPD | K22: {=IFERROR(VLOOKUP(J5,Dex!$B$3:$N102,12,FALSE),"")} -> 70 | L22: {=IFERROR(VLOOKUP(K22,Dex!$P$22:$Q$276,2,FALSE),"")} | M22: 4 | O22: SPD | P22: {=IFERROR(VLOOKUP(O5,Dex!$B$3:$N102,12,FALSE),"")} -> 65 | Q22: {=IFERROR(VLOOKUP(P22,Dex!$P$22:$Q$276,2,FALSE),"")} | R22: 4 | T22: SPD | U22: {=IFERROR(VLOOKUP(T5,Dex!$B$3:$N102,12,FALSE),"")} -> 100 | V22: {=IFERROR(VLOOKUP(U22,Dex!$P$22:$Q$276,2,FALSE),"")} | W22: 4 | Y22: SPD | Z22: {=IFERROR(VLOOKUP(Y5,Dex!$B$3:$N102,12,FALSE),"")} -> 80 | AA22: {=IFERROR(VLOOKUP(Z22,Dex!$P$22:$Q$276,2,FALSE),"")} | AB22: 4 | AD22: SPD | AE22: {=IFERROR(VLOOKUP(AD5,Dex!$B$3:$N102,12,FALSE),"")} -> 95 | AF22: {=IFERROR(VLOOKUP(AE22,Dex!$P$22:$Q$276,2,FALSE),"")} | AG22: 4
C23: IF YOU'RE | E23: SPE | F23: {=IFERROR(VLOOKUP(E5,Dex!$B$3:$N102,13,FALSE),"")} -> 87 | G23: {=IFERROR(VLOOKUP(F23,Dex!$P$22:$Q$276,2,FALSE),"")} | H23: 252 | J23: SPE | K23: {=IFERROR(VLOOKUP(J5,Dex!$B$3:$N102,13,FALSE),"")} -> 55 | L23: {=IFERROR(VLOOKUP(K23,Dex!$P$22:$Q$276,2,FALSE),"")} | M23: 252 | O23: SPE | P23: {=IFERROR(VLOOKUP(O5,Dex!$B$3:$N102,13,FALSE),"")} -> 52 | Q23: {=IFERROR(VLOOKUP(P23,Dex!$P$22:$Q$276,2,FALSE),"")} | T23: SPE | U23: {=IFERROR(VLOOKUP(T5,Dex!$B$3:$N102,13,FALSE),"")} -> 61 | V23: {=IFERROR(VLOOKUP(U23,Dex!$P$22:$Q$276,2,FALSE),"")} | W23: 252 | Y23: SPE | Z23: {=IFERROR(VLOOKUP(Y5,Dex!$B$3:$N102,13,FALSE),"")} -> 90 | AA23: {=IFERROR(VLOOKUP(Z23,Dex!$P$22:$Q$276,2,FALSE),"")} | AB23: 252 | AD23: SPE | AE23: {=IFERROR(VLOOKUP(AD5,Dex!$B$3:$N102,13,FALSE),"")} -> 150 | AF23: {=IFERROR(VLOOKUP(AE23,Dex!$P$22:$Q$276,2,FALSE),"")} | AG23: 252
C24: LEVEL 68 ->> | E24: SPEED STAT: | H24: 199 | J24: SPEED STAT: | M24: 152 | O24: SPEED STAT: | R24: 94 | T24: SPEED STAT: | W24: 161 | Y24: SPEED STAT: | AB24: 203 | AD24: SPEED STAT: | AG24: 291
J25: 1 WEAK ARM.: | M25: 304
E28: BATTLE EFFECT: PERMANENT RAIN
C29: =IMAGE("https://i.ibb.co/mh2zYn4/Misty.png") | E29: {=IFERROR(VLOOKUP(E30,Dex!$B$3:$G102,3,FALSE),"")} | J29: {=IFERROR(VLOOKUP(J30,Dex!$B$3:$G102,3,FALSE),"")} | O29: {=IFERROR(VLOOKUP(O30,Dex!$B$3:$G102,3,FALSE),"")} | T29: {=IFERROR(VLOOKUP(T30,Dex!$B$3:$G102,3,FALSE),"")} | Y29: {=IFERROR(VLOOKUP(Y30,Dex!$B$3:$G102,3,FALSE),"")} | AD29: {=IFERROR(VLOOKUP(AD30,Dex!$B$3:$G102,3,FALSE),"")}
C30: GYM LEADER MISTY | E30: Palafin-Hero | J30: Kingdra | O30: Archaludon | T30: Gyarados-Mega | Y30: Ferrothorn | AD30: Gorebyss
E31: Highest Lv -2 | J31: Highest Lv -2 | O31: Highest Lv -2 | T31: Highest Lv -2 | Y31: Highest Lv -2 | AD31: Highest Lv -2
F32: {=IFERROR(VLOOKUP(E30,Dex!$B$3:$H102,5,FALSE),"")} | K32: {=IFERROR(VLOOKUP(J30,Dex!$B$3:$H102,5,FALSE),"")} | L32: {=IFERROR(VLOOKUP(J30,Dex!$B$3:$H102,7,FALSE),"")} | P32: {=IFERROR(VLOOKUP(O30,Dex!$B$3:$H102,5,FALSE),"")} | Q32: {=IFERROR(VLOOKUP(O30,Dex!$B$3:$H102,7,FALSE),"")} | U32: {=IFERROR(VLOOKUP(T30,Dex!$B$3:$H102,5,FALSE),"")} | V32: {=IFERROR(VLOOKUP(T30,Dex!$B$3:$H102,7,FALSE),"")} | Z32: {=IFERROR(VLOOKUP(Y30,Dex!$B$3:$H102,5,FALSE),"")} | AA32: {=IFERROR(VLOOKUP(Y30,Dex!$B$3:$H102,7,FALSE),"")} | AE32: {=IFERROR(VLOOKUP(AD30,Dex!$B$3:$H102,5,FALSE),"")} | AF32: {=IFERROR(VLOOKUP(AD30,Dex!$B$3:$H102,7,FALSE),"")}
E34: Jolly | J34: Jolly | O34: Modest | T34: Jolly | Y34: Relaxed | AD34: Timid
E35: Zero To Hero | J35: Swift Swim | O35: Sturdy | T35: Intimidate Mold Breaker | Y35: Iron Barbs | AD35: Dazzling
E36: Mystic Water | H36: =IMAGE("https://raw.githubusercontent.com/msikma/pokesprite/master/items/hold-item/mystic-water.png",3) | J36: Scope Lens | M36: =IMAGE("https://raw.githubusercontent.com/msikma/pokesprite/master/items/hold-item/scope-lens.png",3) | O36: Leftovers | R36: =IMAGE("https://raw.githubusercontent.com/msikma/pokesprite/master/items/hold-item/leftovers.png",3) | T36: Gyaradosite | W36: =IMAGE("https://raw.githubusercontent.com/msikma/pokesprite/master/items/mega-stone/gyaradosite.png",3) | Y36: Rocky Helmet | AB36: =IMAGE("https://raw.githubusercontent.com/msikma/pokesprite/master/items/hold-item/rocky-helmet.png",3) | AD36: Focus Sash | AG36: =IMAGE("https://raw.githubusercontent.com/msikma/pokesprite/master/items/hold-item/focus-sash.png",3)
E37: Flip Turn | H37: =IMAGE("https://raw.githubusercontent.com/msikma/pokesprite/master/misc/types/gen8/water.png",4,20,20) | J37: Snipe Shot | M37: =IMAGE("https://raw.githubusercontent.com/msikma/pokesprite/master/misc/types/gen8/water.png",4,20,20) | O37: Electro Shot | R37: =IMAGE("https://raw.githubusercontent.com/msikma/pokesprite/master/misc/types/gen8/electric.png",4,20,20) | T37: Dragon Dance | W37: =IMAGE("https://raw.githubusercontent.com/msikma/pokesprite/master/misc/types/gen8/dragon.png",4,20,20) | Y37: Leech Seed | AB37: =IMAGE("https://raw.githubusercontent.com/msikma/pokesprite/master/misc/types/gen8/grass.png",4,20,20) | AD37: Shell Smash | AG37: =IMAGE("https://raw.githubusercontent.com/msikma/pokesprite/master/misc/types/gen8/normal.png",4,20,20)
E38: Wave Crash | H38: =IMAGE("https://raw.githubusercontent.com/msikma/pokesprite/master/misc/types/gen8/water.png",4,20,20) | J38: Dragon Pulse | M38: =IMAGE("https://raw.githubusercontent.com/msikma/pokesprite/master/misc/types/gen8/dragon.png",4,20,20) | O38: Flash Cannon | R38: =IMAGE("https://raw.githubusercontent.com/msikma/pokesprite/master/misc/types/gen8/steel.png",4,20,20) | T38: Waterfall | W38: =IMAGE("https://raw.githubusercontent.com/msikma/pokesprite/master/misc/types/gen8/water.png",4,20,20) | Y38: Gyro Ball | AB38: =IMAGE("https://raw.githubusercontent.com/msikma/pokesprite/master/misc/types/gen8/steel.png",4,20,20) | AD38: Surf | AG38: =IMAGE("https://raw.githubusercontent.com/msikma/pokesprite/master/misc/types/gen8/water.png",4,20,20)
E39: Jet Punch | H39: =IMAGE("https://raw.githubusercontent.com/msikma/pokesprite/master/misc/types/gen8/water.png",4,20,20) | J39: Hurricane | M39: =IMAGE("https://raw.githubusercontent.com/msikma/pokesprite/master/misc/types/gen8/flying.png",4,20,20) | O39: Dragon Pulse | R39: =IMAGE("https://raw.githubusercontent.com/msikma/pokesprite/master/misc/types/gen8/dragon.png",4,20,20) | T39: Crunch | W39: =IMAGE("https://raw.githubusercontent.com/msikma/pokesprite/master/misc/types/gen8/dark.png",4,20,20) | Y39: Power Whip | AB39: =IMAGE("https://raw.githubusercontent.com/msikma/pokesprite/master/misc/types/gen8/grass.png",4,20,20) | AD39: Ice Beam | AG39: =IMAGE("https://raw.githubusercontent.com/msikma/pokesprite/master/misc/types/gen8/ice.png",4,20,20)
E40: Drain Punch | H40: =IMAGE("https://raw.githubusercontent.com/msikma/pokesprite/master/misc/types/gen8/fighting.png",4,20,20) | J40: Ice Beam | M40: =IMAGE("https://raw.githubusercontent.com/msikma/pokesprite/master/misc/types/gen8/ice.png",4,20,20) | O40: Body Press | R40: =IMAGE("https://raw.githubusercontent.com/msikma/pokesprite/master/misc/types/gen8/fighting.png",4,20,20) | T40: Earthquake | W40: =IMAGE("https://raw.githubusercontent.com/msikma/pokesprite/master/misc/types/gen8/ground.png",4,20,20) | Y40: Thunder Wave | AB40: =IMAGE("https://raw.githubusercontent.com/msikma/pokesprite/master/misc/types/gen8/electric.png",4,20,20) | AD40: Moonblast | AG40: =IMAGE("https://raw.githubusercontent.com/msikma/pokesprite/master/misc/types/gen8/fairy.png",4,20,20)
E42: BASE STATS | H42: EVs | J42: BASE STATS | M42: EVs | O42: BASE STATS | R42: EVs | T42: BASE STATS | W42: EVs | Y42: BASE STATS | AB42: EVs | AD42: BASE STATS | AG42: EVs
E43: HP | F43: {=IFERROR(VLOOKUP(E30,Dex!$B$3:$N102,8,FALSE),"")} -> 100 | G43: {=IFERROR(VLOOKUP(F43,Dex!$P$22:$Q$276,2,FALSE),"")} | J43: HP | K43: {=IFERROR(VLOOKUP(J30,Dex!$B$3:$N102,8,FALSE),"")} -> 75 | L43: {=IFERROR(VLOOKUP(K43,Dex!$P$22:$Q$276,2,FALSE),"")} | O43: HP | P43: {=IFERROR(VLOOKUP(O30,Dex!$B$3:$N102,8,FALSE),"")} -> 90 | Q43: {=IFERROR(VLOOKUP(P43,Dex!$P$22:$Q$276,2,FALSE),"")} | R43: 252 | T43: HP | U43: {=IFERROR(VLOOKUP(T30,Dex!$B$3:$N102,8,FALSE),"")} -> 95 | V43: {=IFERROR(VLOOKUP(U43,Dex!$P$22:$Q$276,2,FALSE),"")} | Y43: HP | Z43: {=IFERROR(VLOOKUP(Y30,Dex!$B$3:$N102,8,FALSE),"")} -> 74 | AA43: {=IFERROR(VLOOKUP(Z43,Dex!$P$22:$Q$276,2,FALSE),"")} | AB43: 252 | AD43: HP | AE43: {=IFERROR(VLOOKUP(AD30,Dex!$B$3:$N102,8,FALSE),"")} -> 55 | AF43: {=IFERROR(VLOOKUP(AE43,Dex!$P$22:$Q$276,2,FALSE),"")}
E44: ATK | F44: {=IFERROR(VLOOKUP(E30,Dex!$B$3:$N102,9,FALSE),"")} -> 160 | G44: {=IFERROR(VLOOKUP(F44,Dex!$P$22:$Q$276,2,FALSE),"")} | H44: 252 | J44: ATK | K44: {=IFERROR(VLOOKUP(J30,Dex!$B$3:$N102,9,FALSE),"")} -> 95 | L44: {=IFERROR(VLOOKUP(K44,Dex!$P$22:$Q$276,2,FALSE),"")} | O44: ATK | P44: {=IFERROR(VLOOKUP(O30,Dex!$B$3:$N102,9,FALSE),"")} -> 105 | Q44: {=IFERROR(VLOOKUP(P44,Dex!$P$22:$Q$276,2,FALSE),"")} | T44: ATK | U44: {=IFERROR(VLOOKUP(T30,Dex!$B$3:$N102,9,FALSE),"")} -> 155 | V44: {=IFERROR(VLOOKUP(U44,Dex!$P$22:$Q$276,2,FALSE),"")} | W44: 252 | Y44: ATK | Z44: {=IFERROR(VLOOKUP(Y30,Dex!$B$3:$N102,9,FALSE),"")} -> 94 | AA44: {=IFERROR(VLOOKUP(Z44,Dex!$P$22:$Q$276,2,FALSE),"")} | AD44: ATK | AE44: {=IFERROR(VLOOKUP(AD30,Dex!$B$3:$N102,9,FALSE),"")} -> 84 | AF44: {=IFERROR(VLOOKUP(AE44,Dex!$P$22:$Q$276,2,FALSE),"")}
E45: DEF | F45: {=IFERROR(VLOOKUP(E30,Dex!$B$3:$N102,10,FALSE),"")} -> 97 | G45: {=IFERROR(VLOOKUP(F45,Dex!$P$22:$Q$276,2,FALSE),"")} | J45: DEF | K45: {=IFERROR(VLOOKUP(J30,Dex!$B$3:$N102,10,FALSE),"")} -> 95 | L45: {=IFERROR(VLOOKUP(K45,Dex!$P$22:$Q$276,2,FALSE),"")} | O45: DEF | P45: {=IFERROR(VLOOKUP(O30,Dex!$B$3:$N102,10,FALSE),"")} -> 130 | Q45: {=IFERROR(VLOOKUP(P45,Dex!$P$22:$Q$276,2,FALSE),"")} | R45: 4 | T45: DEF | U45: {=IFERROR(VLOOKUP(T30,Dex!$B$3:$N102,10,FALSE),"")} -> 109 | V45: {=IFERROR(VLOOKUP(U45,Dex!$P$22:$Q$276,2,FALSE),"")} | Y45: DEF | Z45: {=IFERROR(VLOOKUP(Y30,Dex!$B$3:$N102,10,FALSE),"")} -> 131 | AA45: {=IFERROR(VLOOKUP(Z45,Dex!$P$22:$Q$276,2,FALSE),"")} | AB45: 252 | AD45: DEF | AE45: {=IFERROR(VLOOKUP(AD30,Dex!$B$3:$N102,10,FALSE),"")} -> 105 | AF45: {=IFERROR(VLOOKUP(AE45,Dex!$P$22:$Q$276,2,FALSE),"")}
E46: SPA | F46: {=IFERROR(VLOOKUP(E30,Dex!$B$3:$N102,11,FALSE),"")} -> 106 | G46: {=IFERROR(VLOOKUP(F46,Dex!$P$22:$Q$276,2,FALSE),"")} | J46: SPA | K46: {=IFERROR(VLOOKUP(J30,Dex!$B$3:$N102,11,FALSE),"")} -> 95 | L46: {=IFERROR(VLOOKUP(K46,Dex!$P$22:$Q$276,2,FALSE),"")} | M46: 252 | O46: SPA | P46: {=IFERROR(VLOOKUP(O30,Dex!$B$3:$N102,11,FALSE),"")} -> 125 | Q46: {=IFERROR(VLOOKUP(P46,Dex!$P$22:$Q$276,2,FALSE),"")} | R46: 252 | T46: SPA | U46: {=IFERROR(VLOOKUP(T30,Dex!$B$3:$N102,11,FALSE),"")} -> 70 | V46: {=IFERROR(VLOOKUP(U46,Dex!$P$22:$Q$276,2,FALSE),"")} | Y46: SPA | Z46: {=IFERROR(VLOOKUP(Y30,Dex!$B$3:$N102,11,FALSE),"")} -> 54 | AA46: {=IFERROR(VLOOKUP(Z46,Dex!$P$22:$Q$276,2,FALSE),"")} | AD46: SPA | AE46: {=IFERROR(VLOOKUP(AD30,Dex!$B$3:$N102,11,FALSE),"")} -> 104 | AF46: {=IFERROR(VLOOKUP(AE46,Dex!$P$22:$Q$276,2,FALSE),"")} | AG46: 252
E47: SPD | F47: {=IFERROR(VLOOKUP(E30,Dex!$B$3:$N102,12,FALSE),"")} -> 87 | G47: {=IFERROR(VLOOKUP(F47,Dex!$P$22:$Q$276,2,FALSE),"")} | H47: 4 | J47: SPD | K47: {=IFERROR(VLOOKUP(J30,Dex!$B$3:$N102,12,FALSE),"")} -> 95 | L47: {=IFERROR(VLOOKUP(K47,Dex!$P$22:$Q$276,2,FALSE),"")} | M47: 4 | O47: SPD | P47: {=IFERROR(VLOOKUP(O30,Dex!$B$3:$N102,12,FALSE),"")} -> 65 | Q47: {=IFERROR(VLOOKUP(P47,Dex!$P$22:$Q$276,2,FALSE),"")} | T47: SPD | U47: {=IFERROR(VLOOKUP(T30,Dex!$B$3:$N102,12,FALSE),"")} -> 130 | V47: {=IFERROR(VLOOKUP(U47,Dex!$P$22:$Q$276,2,FALSE),"")} | W47: 4 | Y47: SPD | Z47: {=IFERROR(VLOOKUP(Y30,Dex!$B$3:$N102,12,FALSE),"")} -> 116 | AA47: {=IFERROR(VLOOKUP(Z47,Dex!$P$22:$Q$276,2,FALSE),"")} | AB47: 4 | AD47: SPD | AE47: {=IFERROR(VLOOKUP(AD30,Dex!$B$3:$N102,12,FALSE),"")} -> 75 | AF47: {=IFERROR(VLOOKUP(AE47,Dex!$P$22:$Q$276,2,FALSE),"")} | AG47: 4
C48: IF YOU'RE | E48: SPE | F48: {=IFERROR(VLOOKUP(E30,Dex!$B$3:$N102,13,FALSE),"")} -> 100 | G48: {=IFERROR(VLOOKUP(F48,Dex!$P$22:$Q$276,2,FALSE),"")} | H48: 252 | J48: SPE | K48: {=IFERROR(VLOOKUP(J30,Dex!$B$3:$N102,13,FALSE),"")} -> 85 | L48: {=IFERROR(VLOOKUP(K48,Dex!$P$22:$Q$276,2,FALSE),"")} | M48: 252 | O48: SPE | P48: {=IFERROR(VLOOKUP(O30,Dex!$B$3:$N102,13,FALSE),"")} -> 85 | Q48: {=IFERROR(VLOOKUP(P48,Dex!$P$22:$Q$276,2,FALSE),"")} | T48: SPE | U48: {=IFERROR(VLOOKUP(T30,Dex!$B$3:$N102,13,FALSE),"")} -> 81 | V48: {=IFERROR(VLOOKUP(U48,Dex!$P$22:$Q$276,2,FALSE),"")} | W48: 252 | Y48: SPE | Z48: {=IFERROR(VLOOKUP(Y30,Dex!$B$3:$N102,13,FALSE),"")} -> 20 | AA48: {=IFERROR(VLOOKUP(Z48,Dex!$P$22:$Q$276,2,FALSE),"")} | AD48: SPE | AE48: {=IFERROR(VLOOKUP(AD30,Dex!$B$3:$N102,13,FALSE),"")} -> 52 | AF48: {=IFERROR(VLOOKUP(AE48,Dex!$P$22:$Q$276,2,FALSE),"")} | AG48: 252
...

Sheet Johto Leaders
C3: =IMAGE("https://i.ibb.co/gMdPsRL/Falkner.png") | E3: {=IFERROR(VLOOKUP(E4,Dex!$B$3:$G244,3,FALSE),"")} | J3: {=IFERROR(VLOOKUP(J4,Dex!$B$3:$G244,3,FALSE),"")} | O3: {=IFERROR(VLOOKUP(O4,Dex!$B$3:$G244,3,FALSE),"")}
C4: PEWTER MUSEUM LEADER FALKNER | E4: Rufflet | J4: Wattrel | O4: Flittle
E5: 12 | J5: 14 | O5: 14
F6: {=IFERROR(VLOOKUP(E4,Dex!$B$3:$H244,5,FALSE),"")} | G6: {=IFERROR(VLOOKUP(E4,Dex!$B$3:$H244,7,FALSE),"")} | K6: {=IFERROR(VLOOKUP(J4,Dex!$B$3:$H244,5,FALSE),"")} | L6: {=IFERROR(VLOOKUP(J4,Dex!$B$3:$H244,7,FALSE),"")} | P6: {=IFERROR(VLOOKUP(O4,Dex!$B$3:$H244,5,FALSE),"")}
E8: Jolly | J8: Timid | O8: Bold
E9: Hustle | J9: Volt Absorb | O9: Speed Boost
E10: Berry Juice | H10: =IMAGE("https://raw.githubusercontent.com/msikma/pokesprite/master/items/medicine/berry-juice.png",3) | J10: Berry Juice | M10: =IMAGE("https://raw.githubusercontent.com/msikma/pokesprite/master/items/medicine/berry-juice.png",3) | O10: Eviolite | R10: =IMAGE("https://raw.githubusercontent.com/msikma/pokesprite/master/items/hold-item/eviolite.png",3)
E11: Aerial Ace | H11: =IMAGE("https://raw.githubusercontent.com/msikma/pokesprite/master/misc/types/gen8/flying.png",4,20,20) | J11: Flash | M11: =IMAGE("https://raw.githubusercontent.com/msikma/pokesprite/master/misc/types/gen8/electric.png",4,20,20) | O11: Disarm. Voice | R11: =IMAGE("https://raw.githubusercontent.com/msikma/pokesprite/master/misc/types/gen8/fairy.png",4,20,20)
E12: Rock Tomb | H12: =IMAGE("https://raw.githubusercontent.com/msikma/pokesprite/master/misc/types/gen8/rock.png",4,20,20) | J12: Air Slash | M12: =IMAGE("https://raw.githubusercontent.com/msikma/pokesprite/master/misc/types/gen8/flying.png",4,20,20) | O12: Roost | R12: =IMAGE("https://raw.githubusercontent.com/msikma/pokesprite/master/misc/types/gen8/flying.png",4,20,20)
E13: Rock Smash | H13: =IMAGE("https://raw.githubusercontent.com/msikma/pokesprite/master/misc/types/gen8/fighting.png",4,20,20) | J13: Sleep Talk | M13: =IMAGE("https://raw.githubusercontent.com/msikma/pokesprite/master/misc/types/gen8/normal.png",4,20,20) | O13: Psybeam | R13: =IMAGE("https://raw.githubusercontent.com/msikma/pokesprite/master/misc/types/gen8/psychic.png",4,20,20)
E14: Roost | H14: =IMAGE("https://raw.githubusercontent.com/msikma/pokesprite/master/misc/types/gen8/flying.png",4,20,20) | J14: Roost | M14: =IMAGE("https://raw.githubusercontent.com/msikma/pokesprite/master/misc/types/gen8/flying.png",4,20,20) | O14: Calm Mind | R14: =IMAGE("https://raw.githubusercontent.com/msikma/pokesprite/master/misc/types/gen8/psychic.png",4,20,20)
E16: BASE STATS | H16: EVs | J16: BASE STATS | M16: EVs | O16: BASE STATS | R16: EVs
E17: HP | F17: {=IFERROR(VLOOKUP(E4,Dex!$B$3:$N244,8,FALSE),"")} -> 70 | G17: {=IFERROR(VLOOKUP(F17,Dex!$P$22:$Q$276,2,FALSE),"")} | J17: HP | K17: {=IFERROR(VLOOKUP(J4,Dex!$B$3:$N244,8,FALSE),"")} -> 40 | L17: {=IFERROR(VLOOKUP(K17,Dex!$P$22:$Q$276,2,FALSE),"")} | O17: HP | P17: {=IFERROR(VLOOKUP(O4,Dex!$B$3:$N244,8,FALSE),"")} -> 30 | Q17: {=IFERROR(VLOOKUP(P17,Dex!$P$22:$Q$276,2,FALSE),"")}
E18: ATK | F18: {=IFERROR(VLOOKUP(E4,Dex!$B$3:$N244,9,FALSE),"")} -> 83 | G18: {=IFERROR(VLOOKUP(F18,Dex!$P$22:$Q$276,2,FALSE),"")} | J18: ATK | K18: {=IFERROR(VLOOKUP(J4,Dex!$B$3:$N244,9,FALSE),"")} -> 40 | L18: {=IFERROR(VLOOKUP(K18,Dex!$P$22:$Q$276,2,FALSE),"")} | O18: ATK | P18: {=IFERROR(VLOOKUP(O4,Dex!$B$3:$N244,9,FALSE),"")} -> 35 | Q18: {=IFERROR(VLOOKUP(P18,Dex!$P$22:$Q$276,2,FALSE),"")}
E19: DEF | F19: {=IFERROR(VLOOKUP(E4,Dex!$B$3:$N244,10,FALSE),"")} -> 50 | G19: {=IFERROR(VLOOKUP(F19,Dex!$P$22:$Q$276,2,FALSE),"")} | J19: DEF | K19: {=IFERROR(VLOOKUP(J4,Dex!$B$3:$N244,10,FALSE),"")} -> 35 | L19: {=IFERROR(VLOOKUP(K19,Dex!$P$22:$Q$276,2,FALSE),"")} | O19: DEF | P19: {=IFERROR(VLOOKUP(O4,Dex!$B$3:$N244,10,FALSE),"")} -> 30 | Q19: {=IFERROR(VLOOKUP(P19,Dex!$P$22:$Q$276,2,FALSE),"")}
E20: SPA | F20: {=IFERROR(VLOOKUP(E4,Dex!$B$3:$N244,11,FALSE),"")} -> 37 | G20: {=IFERROR(VLOOKUP(F20,Dex!$P$22:$Q$276,2,FALSE),"")} | J20: SPA | K20: {=IFERROR(VLOOKUP(J4,Dex!$B$3:$N244,11,FALSE),"")} -> 55 | L20: {=IFERROR(VLOOKUP(K20,Dex!$P$22:$Q$276,2,FALSE),"")} | O20: SPA | P20: {=IFERROR(VLOOKUP(O4,Dex!$B$3:$N244,11,FALSE),"")} -> 55 | Q20: {=IFERROR(VLOOKUP(P20,Dex!$P$22:$Q$276,2,FALSE),"")}
E21: SPD | F21: {=IFERROR(VLOOKUP(E4,Dex!$B$3:$N244,12,FALSE),"")} -> 50 | G21: {=IFERROR(VLOOKUP(F21,Dex!$P$22:$Q$276,2,FALSE),"")} | J21: SPD | K21: {=IFERROR(VLOOKUP(J4,Dex!$B$3:$N244,12,FALSE),"")} -> 40 | L21: {=IFERROR(VLOOKUP(K21,Dex!$P$22:$Q$276,2,FALSE),"")} | O21: SPD | P21: {=IFERROR(VLOOKUP(O4,Dex!$B$3:$N244,12,FALSE),"")} -> 30 | Q21: {=IFERROR(VLOOKUP(P21,Dex!$P$22:$Q$276,2,FALSE),"")}
E22: SPE | F22: {=IFERROR(VLOOKUP(E4,Dex!$B$3:$N244,13,FALSE),"")} -> 60 | G22: {=IFERROR(VLOOKUP(F22,Dex!$P$22:$Q$276,2,FALSE),"")} | J22: SPE | K22: {=IFERROR(VLOOKUP(J4,Dex!$B$3:$N244,13,FALSE),"")} -> 70 | L22: {=IFERROR(VLOOKUP(K22,Dex!$P$22:$Q$276,2,FALSE),"")} | O22: SPE | P22: {=IFERROR(VLOOKUP(O4,Dex!$B$3:$N244,13,FALSE),"")} -> 75 | Q22: {=IFERROR(VLOOKUP(P22,Dex!$P$22:$Q$276,2,FALSE),"")}
E23: SPEED STAT: | H23: 25 | J23: SPEED STAT: | M23: 30 | O23: SPEED STAT: | R23: 30
O24: 1 S. BOOST: | R24: 45
E27: (!) PRE LT. SURGE
E29: BATTLE EFFECT: PERMANENT RAIN
C30: =IMAGE("https://i.ibb.co/Lrh0bjy/Bugsy.png") | E30: {=IFERROR(VLOOKUP(E31,Dex!$B$3:$G244,3,FALSE),"")} | J30: {=IFERROR(VLOOKUP(J31,Dex!$B$3:$G244,3,FALSE),"")} | O30: {=IFERROR(VLOOKUP(O31,Dex!$B$3:$G244,3,FALSE),"")} | T30: {=IFERROR(VLOOKUP(T31,Dex!$B$3:$G244,3,FALSE),"")}
C31: ROUTE 25 LEADER BUGSY | E31: Lokix | J31: Ledian | O31: Scyther | T31: Scizor
E32: Highest Lv -2 | J32: Highest Lv -2 | O32: Highest Lv -2 | T32: Highest Lv -2
F33: {=IFERROR(VLOOKUP(E31,Dex!$B$3:$H244,5,FALSE),"")} | G33: {=IFERROR(VLOOKUP(E31,Dex!$B$3:$H244,7,FALSE),"")} | K33: {=IFERROR(VLOOKUP(J31,Dex!$B$3:$H244,5,FALSE),"")} | L33: {=IFERROR(VLOOKUP(J31,Dex!$B$3:$H244,7,FALSE),"")} | P33: {=IFERROR(VLOOKUP(O31,Dex!$B$3:$H244,5,FALSE),"")} | Q33: {=IFERROR(VLOOKUP(O31,Dex!$B$3:$H244,7,FALSE),"")} | U33: {=IFERROR(VLOOKUP(T31,Dex!$B$3:$H244,5,FALSE),"")} | V33: {=IFERROR(VLOOKUP(T31,Dex!$B$3:$H244,7,FALSE),"")}
E35: Jolly | J35: Jolly | O35: Jolly | T35: Careful
E36: Tinted Lens | J36: Iron Fist | O36: Technician | T36: Technician
E37: Silver Powder | H37: =IMAGE("https://raw.githubusercontent.com/msikma/pokesprite/master/items/hold-item/silver-powder.png",3) | J37: Focus Sash | M37: =IMAGE("https://raw.githubusercontent.com/msikma/pokesprite/master/items/hold-item/focus-sash.png",3) | O37: Charti Berry | R37: =IMAGE("https://raw.githubusercontent.com/msikma/pokesprite/master/items/berry/charti.png",3) | T37: Sitrus Berry | W37: =IMAGE("https://raw.githubusercontent.com/msikma/pokesprite/master/items/berry/sitrus.png",3)
E38: First Impress. | H38: =IMAGE("https://raw.githubusercontent.com/msikma/pokesprite/master/misc/types/gen8/bug.png",4,20,20) | J38: Drain Punch | M38: =IMAGE("https://raw.githubusercontent.com/msikma/pokesprite/master/misc/types/gen8/fighting.png",4,20,20) | O38: Bug Bite | R38: =IMAGE("https://raw.githubusercontent.com/msikma/pokesprite/master/misc/types/gen8/bug.png",4,20,20) | T38: Bullet Punch | W38: =IMAGE("https://raw.githubusercontent.com/msikma/pokesprite/master/misc/types/gen8/steel.png",4,20,20)
E39: Knock Off | H39: =IMAGE("https://raw.githubusercontent.com/msikma/pokesprite/master/misc/types/gen8/dark.png",4,20,20) | J39: Mach Punch | M39: =IMAGE("https://raw.githubusercontent.com/msikma/pokesprite/master/misc/types/gen8/fighting.png",4,20,20) | O39: Swords Dance | R39: =IMAGE("https://raw.githubusercontent.com/msikma/pokesprite/master/misc/types/gen8/normal.png",4,20,20) | T39: U-Turn | W39: =IMAGE("https://raw.githubusercontent.com/msikma/pokesprite/master/misc/types/gen8/bug.png",4,20,20)
E40: U-Turn | H40: =IMAGE("https://raw.githubusercontent.com/msikma/pokesprite/master/misc/types/gen8/bug.png",4,20,20) | J40: Ice Punch | M40: =IMAGE("https://raw.githubusercontent.com/msikma/pokesprite/master/misc/types/gen8/ice.png",4,20,20) | O40: Rock Smash | R40: =IMAGE("https://raw.githubusercontent.com/msikma/pokesprite/master/misc/types/gen8/fighting.png",4,20,20) | T40: Rock Smash | W40: =IMAGE("https://raw.githubusercontent.com/msikma/pokesprite/master/misc/types/gen8/fighting.png",4,20,20)
E41: Leech Life | H41: =IMAGE("https://raw.githubusercontent.com/msikma/pokesprite/master/misc/types/gen8/bug.png",4,20,20) | J41: Thunder Punch | M41: =IMAGE("https://raw.githubusercontent.com/msikma/pokesprite/master/misc/types/gen8/electric.png",4,20,20) | O41: Aerial Ace | R41: =IMAGE("https://raw.githubusercontent.com/msikma/pokesprite/master/misc/types/gen8/flying.png",4,20,20) | T41: Aerial Ace | W41: =IMAGE("https://raw.githubusercontent.com/msikma/pokesprite/master/misc/types/gen8/flying.png",4,20,20)
E43: BASE STATS | H43: EVs | J43: BASE STATS | M43: EVs | O43: BASE STATS | R43: EVs | T43: BASE STATS | W43: EVs
E44: HP | F44: {=IFERROR(VLOOKUP(E31,Dex!$B$3:$N244,8,FALSE),"")} -> 71 | G44: {=IFERROR(VLOOKUP(F44,Dex!$P$22:$Q$276,2,FALSE),"")} | J44: HP | K44: {=IFERROR(VLOOKUP(J31,Dex!$B$3:$N244,8,FALSE),"")} -> 55 | L44: {=IFERROR(VLOOKUP(K44,Dex!$P$22:$Q$276,2,FALSE),"")} | O44: HP | P44: {=IFERROR(VLOOKUP(O31,Dex!$B$3:$N244,8,FALSE),"")} -> 70 | Q44: {=IFERROR(VLOOKUP(P44,Dex!$P$22:$Q$276,2,FALSE),"")} | T44: HP | U44: {=IFERROR(VLOOKUP(T31,Dex!$B$3:$N244,8,FALSE),"")} -> 70 | V44: {=IFERROR(VLOOKUP(U44,Dex!$P$22:$Q$276,2,FALSE),"")}
E45: ATK | F45: {=IFERROR(VLOOKUP(E31,Dex!$B$3:$N244,9,FALSE),"")} -> 102 | G45: {=IFERROR(VLOOKUP(F45,Dex!$P$22:$Q$276,2,FALSE),"")} | J45: ATK | K45: {=IFERROR(VLOOKUP(J31,Dex!$B$3:$N244,9,FALSE),"")} -> 90 | L45: {=IFERROR(VLOOKUP(K45,Dex!$P$22:$Q$276,2,FALSE),"")} | O45: ATK | P45: {=IFERROR(VLOOKUP(O31,Dex!$B$3:$N244,9,FALSE),"")} -> 110 | Q45: {=IFERROR(VLOOKUP(P45,Dex!$P$22:$Q$276,2,FALSE),"")} | T45: ATK | U45: {=IFERROR(VLOOKUP(T31,Dex!$B$3:$N244,9,FALSE),"")} -> 130 | V45: {=IFERROR(VLOOKUP(U45,Dex!$P$22:$Q$276,2,FALSE),"")}
E46: DEF | F46: {=IFERROR(VLOOKUP(E31,Dex!$B$3:$N244,10,FALSE),"")} -> 78 | G46: {=IFERROR(VLOOKUP(F46,Dex!$P$22:$Q$276,2,FALSE),"")} | J46: DEF | K46: {=IFERROR(VLOOKUP(J31,Dex!$B$3:$N244,10,FALSE),"")} -> 50 | L46: {=IFERROR(VLOOKUP(K46,Dex!$P$22:$Q$276,2,FALSE),"")} | O46: DEF | P46: {=IFERROR(VLOOKUP(O31,Dex!$B$3:$N244,10,FALSE),"")} -> 80 | Q46: {=IFERROR(VLOOKUP(P46,Dex!$P$22:$Q$276,2,FALSE),"")} | T46: DEF | U46: {=IFERROR(VLOOKUP(T31,Dex!$B$3:$N244,10,FALSE),"")} -> 100 | V46: {=IFERROR(VLOOKUP(U46,Dex!$P$22:$Q$276,2,FALSE),"")}
E47: SPA | F47: {=IFERROR(VLOOKUP(E31,Dex!$B$3:$N244,11,FALSE),"")} -> 52 | G47: {=IFERROR(VLOOKUP(F47,Dex!$P$22:$Q$276,2,FALSE),"")} | J47: SPA | K47: {=IFERROR(VLOOKUP(J31,Dex!$B$3:$N244,11,FALSE),"")} -> 35 | L47: {=IFERROR(VLOOKUP(K47,Dex!$P$22:$Q$276,2,FALSE),"")} | O47: SPA | P47: {=IFERROR(VLOOKUP(O31,Dex!$B$3:$N244,11,FALSE),"")} -> 55 | Q47: {=IFERROR(VLOOKUP(P47,Dex!$P$22:$Q$276,2,FALSE),"")} | T47: SPA | U47: {=IFERROR(VLOOKUP(T31,Dex!$B$3:$N244,11,FALSE),"")} -> 55 | V47: {=IFERROR(VLOOKUP(U47,Dex!$P$22:$Q$276,2,FALSE),"")}
E48: SPD | F48: {=IFERROR(VLOOKUP(E31,Dex!$B$3:$N244,12,FALSE),"")} -> 55 | G48: {=IFERROR(VLOOKUP(F48,Dex!$P$22:$Q$276,2,FALSE),"")} | J48: SPD | K48: {=IFERROR(VLOOKUP(J31,Dex!$B$3:$N244,12,FALSE),"")} -> 100 | L48: {=IFERROR(VLOOKUP(K48,Dex!$P$22:$Q$276,2,FALSE),"")} | O48: SPD | P48: {=IFERROR(VLOOKUP(O31,Dex!$B$3:$N244,12,FALSE),"")} -> 80 | Q48: {=IFERROR(VLOOKUP(P48,Dex!$P$22:$Q$276,2,FALSE),"")} | T48: SPD | U48: {=IFERROR(VLOOKUP(T31,Dex!$B$3:$N244,12,FALSE),"")} -> 80 | V48: {=IFERROR(VLOOKUP(U48,Dex!$P$22:$Q$276,2,FALSE),"")}
C49: IF YOU'RE | E49: SPE | F49: {=IFERROR(VLOOKUP(E31,Dex!$B$3:$N244,13,FALSE),"")} -> 92 | G49: {=IFERROR(VLOOKUP(F49,Dex!$P$22:$Q$276,2,FALSE),"")} | J49: SPE | K49: {=IFERROR(VLOOKUP(J31,Dex!$B$3:$N244,13,FALSE),"")} -> 85 | L49: {=IFERROR(VLOOKUP(K49,Dex!$P$22:$Q$276,2,FALSE),"")} | O49: SPE | P49: {=IFERROR(VLOOKUP(O31,Dex!$B$3:$N244,13,FALSE),"")} -> 105 | Q49: {=IFERROR(VLOOKUP(P49,Dex!$P$22:$Q$276,2,FALSE),"")} | T49: SPE | U49: {=IFERROR(VLOOKUP(T31,Dex!$B$3:$N244,13,FALSE),"")} -> 65 | V49: {=IFERROR(VLOOKUP(U49,Dex!$P$22:$Q$276,2,FALSE),"")}
...

Sheet Rivals
E3: (!) IF RIVAL HAS SQUIRTLE
C5: =IMAGE("https://i.ibb.co/fXwks6z/Rival.png") | E5: {=IFERROR(VLOOKUP(E6,Dex!$B$3:$G415,3,FALSE),"")} | J5: {=IFERROR(VLOOKUP(J6,Dex!$B$3:$G415,3,FALSE),"")}
C6: ROUTE 22 #1 RIVAL | E6: Starly | J6: Squirtle
E7: 9 | J7: 9
F8: {=IFERROR(VLOOKUP(E6,Dex!$B$3:$H415,5,FALSE),"")} | G8: {=IFERROR(VLOOKUP(E6,Dex!$B$3:$H415,7,FALSE),"")} | K8: {=IFERROR(VLOOKUP(J6,Dex!$B$3:$H415,5,FALSE),"")}
E10: Mild | J10: Relaxed
E11: Frisk | J11: Torrent
E12: No Item | H12: X | J12: No Item | M12: X
E13: Tackle | H13: =IMAGE("https://raw.githubusercontent.com/msikma/pokesprite/master/misc/types/gen8/normal.png",4,20,20) | J13: Tackle | M13: =IMAGE("https://raw.githubusercontent.com/msikma/pokesprite/master/misc/types/gen8/normal.png",4,20,20)
E14: Growl | H14: =IMAGE("https://raw.githubusercontent.com/msikma/pokesprite/master/misc/types/gen8/normal.png",4,20,20) | J14: False Swipe | M14: =IMAGE("https://raw.githubusercontent.com/msikma/pokesprite/master/misc/types/gen8/normal.png",4,20,20)
E15: Quick Attack | H15: =IMAGE("https://raw.githubusercontent.com/msikma/pokesprite/master/misc/types/gen8/normal.png",4,20,20) | J15: Tail Whip | M15: =IMAGE("https://raw.githubusercontent.com/msikma/pokesprite/master/misc/types/gen8/normal.png",4,20,20)
E16: Wing Attack | H16: =IMAGE("https://raw.githubusercontent.com/msikma/pokesprite/master/misc/types/gen8/flying.png",4,20,20) | J16: Bubble | M16: =IMAGE("https://raw.githubusercontent.com/msikma/pokesprite/master/misc/types/gen8/water.png",4,20,20)
E18: BASE STATS | H18: EVs | J18: BASE STATS | M18: EVs
E19: HP | F19: {=IFERROR(VLOOKUP(E6,Dex!$B$3:$N415,8,FALSE),"")} -> 40 | G19: {=IFERROR(VLOOKUP(F19,Dex!$P$22:$Q$276,2,FALSE),"")} | J19: HP | K19: {=IFERROR(VLOOKUP(J6,Dex!$B$3:$N415,8,FALSE),"")} -> 44 | L19: {=IFERROR(VLOOKUP(K19,Dex!$P$22:$Q$276,2,FALSE),"")}
E20: ATK | F20: {=IFERROR(VLOOKUP(E6,Dex!$B$3:$N415,9,FALSE),"")} -> 55 | G20: {=IFERROR(VLOOKUP(F20,Dex!$P$22:$Q$276,2,FALSE),"")} | J20: ATK | K20: {=IFERROR(VLOOKUP(J6,Dex!$B$3:$N415,9,FALSE),"")} -> 48 | L20: {=IFERROR(VLOOKUP(K20,Dex!$P$22:$Q$276,2,FALSE),"")}
E21: DEF | F21: {=IFERROR(VLOOKUP(E6,Dex!$B$3:$N415,10,FALSE),"")} -> 30 | G21: {=IFERROR(VLOOKUP(F21,Dex!$P$22:$Q$276,2,FALSE),"")} | J21: DEF | K21: {=IFERROR(VLOOKUP(J6,Dex!$B$3:$N415,10,FALSE),"")} -> 65 | L21: {=IFERROR(VLOOKUP(K21,Dex!$P$22:$Q$276,2,FALSE),"")}
E22: SPA | F22: {=IFERROR(VLOOKUP(E6,Dex!$B$3:$N415,11,FALSE),"")} -> 30 | G22: {=IFERROR(VLOOKUP(F22,Dex!$P$22:$Q$276,2,FALSE),"")} | J22: SPA | K22: {=IFERROR(VLOOKUP(J6,Dex!$B$3:$N415,11,FALSE),"")} -> 50 | L22: {=IFERROR(VLOOKUP(K22,Dex!$P$22:$Q$276,2,FALSE),"")}
E23: SPD | F23: {=IFERROR(VLOOKUP(E6,Dex!$B$3:$N415,12,FALSE),"")} -> 30 | G23: {=IFERROR(VLOOKUP(F23,Dex!$P$22:$Q$276,2,FALSE),"")} | J23: SPD | K23: {=IFERROR(VLOOKUP(J6,Dex!$B$3:$N415,12,FALSE),"")} -> 64 | L23: {=IFERROR(VLOOKUP(K23,Dex!$P$22:$Q$276,2,FALSE),"")}
E24: SPE | F24: {=IFERROR(VLOOKUP(E6,Dex!$B$3:$N415,13,FALSE),"")} -> 60 | G24: {=IFERROR(VLOOKUP(F24,Dex!$P$22:$Q$276,2,FALSE),"")} | J24: SPE | K24: {=IFERROR(VLOOKUP(J6,Dex!$B$3:$N415,13,FALSE),"")} -> 43 | L24: {=IFERROR(VLOOKUP(K24,Dex!$P$22:$Q$276,2,FALSE),"")}
E25: SPEED STAT: | H25: 18 | J25: SPEED STAT: | M25: 12
E27: (!) IF RIVAL HAS CHARMANDER
C29: =IMAGE("https://i.ibb.co/fXwks6z/Rival.png") | E29: {=IFERROR(VLOOKUP(E30,Dex!$B$3:$G415,3,FALSE),"")} | J29: {=IFERROR(VLOOKUP(J30,Dex!$B$3:$G415,3,FALSE),"")}
C30: ROUTE 22 #1 RIVAL | E30: Starly | J30: Charmander
E31: 9 | J31: 9
F32: {=IFERROR(VLOOKUP(E30,Dex!$B$3:$H415,5,FALSE),"")} | G32: {=IFERROR(VLOOKUP(E30,Dex!$B$3:$H415,7,FALSE),"")} | K32: {=IFERROR(VLOOKUP(J30,Dex!$B$3:$H415,5,FALSE),"")}
E34: Mild | J34: Timid
E35: Frisk | J35: Blaze
E36: No Item | H36: X | J36: No Item | M36: X
E37: Tackle | H37: =IMAGE("https://raw.githubusercontent.com/msikma/pokesprite/master/misc/types/gen8/normal.png",4,20,20) | J37: Growl | M37: =IMAGE("https://raw.githubusercontent.com/msikma/pokesprite/master/misc/types/gen8/normal.png",4,20,20)
E38: Growl | H38: =IMAGE("https://raw.githubusercontent.com/msikma/pokesprite/master/misc/types/gen8/normal.png",4,20,20) | J38: False Swipe | M38: =IMAGE("https://raw.githubusercontent.com/msikma/pokesprite/master/misc/types/gen8/normal.png",4,20,20)
E39: Quick Attack | H39: =IMAGE("https://raw.githubusercontent.com/msikma/pokesprite/master/misc/types/gen8/normal.png",4,20,20) | J39: Ember | M39: =IMAGE("https://raw.githubusercontent.com/msikma/pokesprite/master/misc/types/gen8/fire.png",4,20,20)
E40: Wing Attack | H40: =IMAGE("https://raw.githubusercontent.com/msikma/pokesprite/master/misc/types/gen8/flying.png",4,20,20) | J40: Brick Break | M40: =IMAGE("https://raw.githubusercontent.com/msikma/pokesprite/master/misc/types/gen8/fighting.png",4,20,20)
E42: BASE STATS | H42: EVs | J42: BASE STATS | M42: EVs
E43: HP | F43: {=IFERROR(VLOOKUP(E30,Dex!$B$3:$N415,8,FALSE),"")} -> 40 | G43: {=IFERROR(VLOOKUP(F43,Dex!$P$22:$Q$276,2,FALSE),"")} | J43: HP | K43: {=IFERROR(VLOOKUP(J30,Dex!$B$3:$N415,8,FALSE),"")} -> 39 | L43: {=IFERROR(VLOOKUP(K43,Dex!$P$22:$Q$276,2,FALSE),"")}
E44: ATK | F44: {=IFERROR(VLOOKUP(E30,Dex!$B$3:$N415,9,FALSE),"")} -> 55 | G44: {=IFERROR(VLOOKUP(F44,Dex!$P$22:$Q$276,2,FALSE),"")} | J44: ATK | K44: {=IFERROR(VLOOKUP(J30,Dex!$B$3:$N415,9,FALSE),"")} -> 52 | L44: {=IFERROR(VLOOKUP(K44,Dex!$P$22:$Q$276,2,FALSE),"")}
E45: DEF | F45: {=IFERROR(VLOOKUP(E30,Dex!$B$3:$N415,10,FALSE),"")} -> 30 | G45: {=IFERROR(VLOOKUP(F45,Dex!$P$22:$Q$276,2,FALSE),"")} | J45: DEF | K45: {=IFERROR(VLOOKUP(J30,Dex!$B$3:$N415,10,FALSE),"")} -> 43 | L45: {=IFERROR(VLOOKUP(K45,Dex!$P$22:$Q$276,2,FALSE),"")}
E46: SPA | F46: {=IFERROR(VLOOKUP(E30,Dex!$B$3:$N415,11,FALSE),"")} -> 30 | G46: {=IFERROR(VLOOKUP(F46,Dex!$P$22:$Q$276,2,FALSE),"")} | J46: SPA | K46: {=IFERROR(VLOOKUP(J30,Dex!$B$3:$N415,11,FALSE),"")} -> 60 | L46: {=IFERROR(VLOOKUP(K46,Dex!$P$22:$Q$276,2,FALSE),"")}
E47: SPD | F47: {=IFERROR(VLOOKUP(E30,Dex!$B$3:$N415,12,FALSE),"")} -> 30 | G47: {=IFERROR(VLOOKUP(F47,Dex!$P$22:$Q$276,2,FALSE),"")} | J47: SPD | K47: {=IFERROR(VLOOKUP(J30,Dex!$B$3:$N415,12,FALSE),"")} -> 50 | L47: {=IFERROR(VLOOKUP(K47,Dex!$P$22:$Q$276,2,FALSE),"")}
E48: SPE | F48: {=IFERROR(VLOOKUP(E30,Dex!$B$3:$N415,13,FALSE),"")} -> 60 | G48: {=IFERROR(VLOOKUP(F48,Dex!$P$22:$Q$276,2,FALSE),"")} | J48: SPE | K48: {=IFERROR(VLOOKUP(J30,Dex!$B$3:$N415,13,FALSE),"")} -> 65 | L48: {=IFERROR(VLOOKUP(K48,Dex!$P$22:$Q$276,2,FALSE),"")}
E49: SPEED STAT: | H49: 18 | J49: SPEED STAT: | M49: 19
...

Sheet Team Rocket
C3: =IMAGE("https://i.ibb.co/xhnkr2Z/Archer.png") | E3: {=IFERROR(VLOOKUP(E4,Dex!$B$3:$G330,3,FALSE),"")} | J3: {=IFERROR(VLOOKUP(J4,Dex!$B$3:$G330,3,FALSE),"")} | O3: {=IFERROR(VLOOKUP(O4,Dex!$B$3:$G330,3,FALSE),"")}
C4: MT. MOON ARCHER | E4: Glimmet | J4: Houndour | O4: Mightyena
E5: 18 | J5: 19 | O5: 21
F6: {=IFERROR(VLOOKUP(E4,Dex!$B$3:$H330,5,FALSE),"")} | G6: {=IFERROR(VLOOKUP(E4,Dex!$B$3:$H330,7,FALSE),"")} | K6: {=IFERROR(VLOOKUP(J4,Dex!$B$3:$H330,5,FALSE),"")} | L6: {=IFERROR(VLOOKUP(J4,Dex!$B$3:$H330,7,FALSE),"")} | P6: {=IFERROR(VLOOKUP(O4,Dex!$B$3:$H330,5,FALSE),"")}
E8: Timid | J8: Timid | O8: Jolly
E9: Toxic Debris | J9: Unnerve | O9: Strong Jaw
E10: Shuca Berry | H10: =IMAGE("https://raw.githubusercontent.com/msikma/pokesprite/master/items/berry/shuca.png",3) | J10: Wise Glasses | M10: =IMAGE("https://raw.githubusercontent.com/msikma/pokesprite/master/items/hold-item/wise-glasses.png",3) | O10: Berry Juice | R10: =IMAGE("https://raw.githubusercontent.com/msikma/pokesprite/master/items/medicine/berry-juice.png",3)
