Workbook

Sheet Main
C3: PLEASE CHECK THE OTHER TABS AT THE BOTTOM! THIS IS ONLY THE FIRST TAB.
C4: IT IS RECOMMENDED THAT YOU ZOOM OUT TO SEE EVERYTHING BETTER.
C5: CLICK/TAP THE LINK INSIDE THAT BOX TO ACCESS THE TRAINER ORDER.
C6: REPORT MISTAKES IN THE #DOCUMENTATION-REPORTS CHANNEL ON OUR DISCORD SERVER.
C8: HARDCORE GENERAL RESTRICTIONS AND CHANGES
E10: Weather / Terrain set by the AI's Pokémon is permanent.
E12: Defog, Steel Roller, Ice Spinner and Splintered Stormshards do not remove terrain.
E14: Electric Seed is unobtainable from wild Pokémon before beating Lt. Surge.
E16: Misty Seed is unobtainable from wild Pokémon before beating Sabrina.
E18: Psychic Seed is unobtainable from wild Pokémon before beating Koga.
E20: Your follower Pokémon cannot pick up an Eject Button in Power Plant.
E22: The first four Level Caps are different (see the Level Caps below).
E24: The location of Charizardite Y and Charizardite X are swapped.
E26: The location of Gardevoirite and Cameruptite are swapped.
E28: Rapid Spin does not boost speed.
E30: Moves that have a chance to Omniboost can't give boosts to the player.
E32: Shedinja is unobtainable.
... E40: Psyshock TM is given by Sabrina and not found on Underground Path.
C42: LEVEL CAPS
E44: Pre-Brock (16)
E46: Pre-Mt. Moon Archer (23)
E48: Pre-Misty (28)
E50: Pre-Lt. Surge (36)
E52: Pre-Erika (44)
E54: Pre-Game Corner Giovanni (47)
E56: Pre-Silph Co. Archer & Ariana (56)
E58: Pre-Giovanni Silph Co. (57)
E60: Pre-Sabrina (59)
E62: Pre-Koga (68)
E64: Pre-May (73)
E66: Pre-Blaine (76)
... E78: Post Game (100)
C80: HOW TO GET FOCUS SASH AND CHOICE ITEMS FROM QUESTS
E81: Show a Pokémon with 125+ base stat in the respective stat (Chuck asks for a Pokémon with strong attack, show a mon with 125+ base attack like Terrakion).
C83: ABOUT THE SHEET
E85: All of the trainer info in this sheet should be 100% accurate, because it was either obtained via byte copying and using the Stat Scanner, or thanks to source code data.
E87: Even if something looks VERY wrong, that's how it is in-game. Though, feel free to report text typos if you ever find those.
E89: All of the opposing Pokémon's moves in this sheet are PP maxed.
E91: Generally, if a Pokémon has Gyro Ball in its moveset or is part of a Trick Room team, you can safely assume it has zero speed IVs.
E93: Rival's chosen starter determines what team he gets. If he has the Squirtle team, that means the player chose a Fire-type starter Pokémon.
...

Sheet Trainer Order
C3: (!) CLICK ON TRAINER'S NAME TO INSTANTLY GO TO PAGE! | F3: LEVEL CAPS
C5: (OPTIONAL)
C6: =IMAGE("https://i.ibb.co/fXwks6z/Rival.png",4,150,150) | D6: RIVAL | F6: 16
D7: ROUTE 22
C10: =IMAGE("https://i.ibb.co/10ZXyNx/Brendan.png",4,150,150) | D10: BRENDAN | F10: 16
D11: VIRIDIAN FOREST
C14: =IMAGE("https://i.ibb.co/8sm893K/Lass.png",4,150,150) | D14: LASS ANNE | F14: 16
D15: VIRIDIAN FOREST
C18: (OPTIONAL)
C19: =IMAGE("https://i.ibb.co/26kF6WW/Ace-Trainer-F.png",4,150,150) | D19: ACE NELLE | F19: 16+
D20: VIRIDIAN FOREST
C23: =IMAGE("https://i.ibb.co/8D0GLzq/Bug-Catcher.png",4,150,150) | D23: CATCHER SAMMY | F23: 16
D24: VIRIDIAN FOREST
C27: =IMAGE("https://i.ibb.co/NWQ5Qdk/Falkner.png",4,150,150) | D27: FALKNER | F27: 16
D28: PEWTER CITY
C31: =IMAGE("https://i.ibb.co/RBhc6sL/Brock.png",4,150,150) | D31: BROCK | F31: 16
D32: PEWTER CITY
C35: =IMAGE("https://i.ibb.co/8sm893K/Lass.png",4,150,150) | D35: LASS SALLY | F35: 23
D36: ROUTE 3
C39: =IMAGE("https://i.ibb.co/zFMzgnB/Super-Nerd.png",4,150,150) | D39: SUPER NERD MIGUEL | F39: 23
D40: MT. MOON
C43: =IMAGE("https://i.ibb.co/xhnkr2Z/Archer.png",4,150,150) | D43: ARCHER | F43: 23
D44: MT. MOON
C47: =IMAGE("https://i.ibb.co/fXwks6z/Rival.png",4,150,150) | D47: RIVAL | F47: 28/36
D48: CERULEAN CITY
C51: =IMAGE("https://i.ibb.co/8D0GLzq/Bug-Catcher.png",4,150,150) | D51: CATCHER CALE | F51: 28/36
D52: NUGGET BRIDGE
C55: =IMAGE("https://i.ibb.co/8sm893K/Lass.png",4,150,150) | D55: LASS ALI | F55: 28/36
D56: NUGGET BRIDGE
C59: =IMAGE("https://i.ibb.co/6nGd7Gm/Youngster.png",4,150,150) | D59: YOUNGSTER TIMMY | F59: 28/36
D60: NUGGET BRIDGE
C63: =IMAGE("https://i.ibb.co/8sm893K/Lass.png",4,150,150) | D63: LASS RELLI | F63: 28/36
D64: NUGGET BRIDGE
C67: =IMAGE("https://i.ibb.co/VxD4KtV/Camper.png",4,150,150) | D67: CAMPER ETHAN | F67: 28/36
D68: NUGGET BRIDGE
C71: =IMAGE("https://i.ibb.co/FzKmMqb/Grunt.png",4,150,150) | D71: GRUNT | F71: 28/36
D72: NUGGET BRIDGE
C75: (OPTIONAL)
C76: =IMAGE("https://i.ibb.co/Lrh0bjy/Bugsy.png",4,150,150) | D76: BUGSY | F76: 28+
D77: ROUTE 25
...

Sheet Kanto Leaders
E3: BATTLE EFFECT: PERMANENT SANDSTORM
C4: =IMAGE("https://i.ibb.co/v10Rh61/Brock.png") | E4: {=IFERROR(VLOOKUP(E5,Dex!$B$3:$G200,3,FALSE),"")} | J4: {=IFERROR(VLOOKUP(J5,Dex!$B$3:$G200,3,FALSE),"")} | O4: {=IFERROR(VLOOKUP(O5,Dex!$B$3:$G200,3,FALSE),"")} | T4: {=IFERROR(VLOOKUP(T5,Dex!$B$3:$G200,3,FALSE),"")} | Y4: {=IFERROR(VLOOKUP(Y5,Dex!$B$3:$G200,3,FALSE),"")} | AD4: {=IFERROR(VLOOKUP(AD5,Dex!$B$3:$G200,3,FALSE),"")}
C5: GYM LEADER BROCK | E5: Hippopotas | J5: Cacnea | O5: Lunatone | T5: Lileep | Y5: Archen | AD5: Varoom
E6: 13 | J6: 15 | O6: 14 | T6: 16 | Y6: 14 | AD6: 15
F7: {=IFERROR(VLOOKUP(E5,Dex!$B$3:$H200,5,FALSE),"")} | K7: {=IFERROR(VLOOKUP(J5,Dex!$B$3:$H200,5,FALSE),"")} | P7: {=IFERROR(VLOOKUP(O5,Dex!$B$3:$H200,5,FALSE),"")} | Q7: {=IFERROR(VLOOKUP(O5,Dex!$B$3:$H200,7,FALSE),"")} | U7: {=IFERROR(VLOOKUP(T5,Dex!$B$3:$H200,5,FALSE),"")} | V7: {=IFERROR(VLOOKUP(T5,Dex!$B$3:$H200,7,FALSE),"")} | Z7: {=IFERROR(VLOOKUP(Y5,Dex!$B$3:$H200,5,FALSE),"")} | AA7: {=IFERROR(VLOOKUP(Y5,Dex!$B$3:$H200,7,FALSE),"")} | AE7: {=IFERROR(VLOOKUP(AD5,Dex!$B$3:$H200,5,FALSE),"")} | AF7: {=IFERROR(VLOOKUP(AD5,Dex!$B$3:$H200,7,FALSE),"")}
E9: Careful | J9: Bashful | O9: Bashful | T9: Bold | Y9: Bashful | AD9: Careful
E10: Sand Stream | J10: Sand Rush | O10: Levitate | T10: Storm Drain | Y10: Defeatist | AD10: Filter
E11: Berry Juice | H11: =IMAGE("https://raw.githubusercontent.com/msikma/pokesprite/master/items/medicine/berry-juice.png",3) | J11: Eviolite | M11: =IMAGE("https://raw.githubusercontent.com/msikma/pokesprite/master/items/hold-item/eviolite.png",3) | O11: Lum Berry | R11: =IMAGE("https://raw.githubusercontent.com/msikma/pokesprite/master/items/berry/lum.png",3) | T11: Oran Berry | W11: =IMAGE("https://raw.githubusercontent.com/msikma/pokesprite/master/items/berry/oran.png",4,28,28) | Y11: Iapapa Berry | AB11: =IMAGE("https://raw.githubusercontent.com/msikma/pokesprite/master/items/berry/iapapa.png",3) | AD11: Air Balloon | AG11: =IMAGE("https://raw.githubusercontent.com/msikma/pokesprite/master/items/hold-item/air-balloon.png",3)
E12: Bulldoze | H12: =IMAGE("https://raw.githubusercontent.com/msikma/pokesprite/master/misc/types/gen8/ground.png",4,20,20) | J12: Pow-Up Punch | M12: =IMAGE("https://raw.githubusercontent.com/msikma/pokesprite/master/misc/types/gen8/fighting.png",4,20,20) | O12: Ancient Power | R12: =IMAGE("https://raw.githubusercontent.com/msikma/pokesprite/master/misc/types/gen8/rock.png",4,20,20) | T12: Stockpile | W12: =IMAGE("https://raw.githubusercontent.com/msikma/pokesprite/master/misc/types/gen8/normal.png",4,20,20) | Y12: Wing Attack | AB12: =IMAGE("https://raw.githubusercontent.com/msikma/pokesprite/master/misc/types/gen8/flying.png",4,20,20) | AD12: Bulldoze | AG12: =IMAGE("https://raw.githubusercontent.com/msikma/pokesprite/master/misc/types/gen8/ground.png",4,20,20)
E13: Rock Tomb | H13: =IMAGE("https://raw.githubusercontent.com/msikma/pokesprite/master/misc/types/gen8/rock.png",4,20,20) | J13: Bullet Seed | M13: =IMAGE("https://raw.githubusercontent.com/msikma/pokesprite/master/misc/types/gen8/grass.png",4,20,20) | O13: Psybeam | R13: =IMAGE("https://raw.githubusercontent.com/msikma/pokesprite/master/misc/types/gen8/psychic.png",4,20,20) | T13: Recover | W13: =IMAGE("https://raw.githubusercontent.com/msikma/pokesprite/master/misc/types/gen8/normal.png",4,20,20) | Y13: Rock Tomb | AB13: =IMAGE("https://raw.githubusercontent.com/msikma/pokesprite/master/misc/types/gen8/rock.png",4,20,20) | AD13: Gyro Ball | AG13: =IMAGE("https://raw.githubusercontent.com/msikma/pokesprite/master/misc/types/gen8/steel.png",4,20,20)
E14: Toxic | H14: =IMAGE("https://raw.githubusercontent.com/msikma/pokesprite/master/misc/types/gen8/poison.png",4,20,20) | J14: Thunder Punch | M14: =IMAGE("https://raw.githubusercontent.com/msikma/pokesprite/master/misc/types/gen8/electric.png",4,20,20) | O14: HP Ground | R14: =IMAGE("https://raw.githubusercontent.com/msikma/pokesprite/master/misc/types/gen8/ground.png",4,20,20) | T14: HP Rock | W14: =IMAGE("https://raw.githubusercontent.com/msikma/pokesprite/master/misc/types/gen8/rock.png",4,20,20) | Y14: Bulldoze | AB14: =IMAGE("https://raw.githubusercontent.com/msikma/pokesprite/master/misc/types/gen8/ground.png",4,20,20) | AD14: Toxic | AG14: =IMAGE("https://raw.githubusercontent.com/msikma/pokesprite/master/misc/types/gen8/poison.png",4,20,20)
E15: Slack Off | H15: =IMAGE("https://raw.githubusercontent.com/msikma/pokesprite/master/misc/types/gen8/normal.png",4,20,20) | J15: Pin Missile | M15: =IMAGE("https://raw.githubusercontent.com/msikma/pokesprite/master/misc/types/gen8/bug.png",4,20,20) | O15: Icy Wind | R15: =IMAGE("https://raw.githubusercontent.com/msikma/pokesprite/master/misc/types/gen8/ice.png",4,20,20) | T15: Mega Drain | W15: =IMAGE("https://raw.githubusercontent.com/msikma/pokesprite/master/misc/types/gen8/grass.png",4,20,20) | Y15: Facade | AB15: =IMAGE("https://raw.githubusercontent.com/msikma/pokesprite/master/misc/types/gen8/normal.png",4,20,20) | AD15: Protect | AG15: =IMAGE("https://raw.githubusercontent.com/msikma/pokesprite/master/misc/types/gen8/normal.png",4,20,20)
E17: BASE STATS | J17: BASE STATS | O17: BASE STATS | T17: BASE STATS | Y17: BASE STATS | AD17: BASE STATS
E18: HP | F18: {=IFERROR(VLOOKUP(E5,Dex!$B$3:$N200,8,FALSE),"")} -> 68 | G18: {=IFERROR(VLOOKUP(F18,Dex!$P$22:$Q$276,2,FALSE),"")} | J18: HP | K18: {=IFERROR(VLOOKUP(J5,Dex!$B$3:$N200,8,FALSE),"")} -> 50 | L18: {=IFERROR(VLOOKUP(K18,Dex!$P$22:$Q$276,2,FALSE),"")} | O18: HP | P18: {=IFERROR(VLOOKUP(O5,Dex!$B$3:$N200,8,FALSE),"")} -> 90 | Q18: {=IFERROR(VLOOKUP(P18,Dex!$P$22:$Q$276,2,FALSE),"")} | T18: HP | U18: {=IFERROR(VLOOKUP(T5,Dex!$B$3:$N200,8,FALSE),"")} -> 66 | V18: {=IFERROR(VLOOKUP(U18,Dex!$P$22:$Q$276,2,FALSE),"")} | Y18: HP | Z18: {=IFERROR(VLOOKUP(Y5,Dex!$B$3:$N200,8,FALSE),"")} -> 55 | AA18: {=IFERROR(VLOOKUP(Z18,Dex!$P$22:$Q$276,2,FALSE),"")} | AD18: HP | AE18: {=IFERROR(VLOOKUP(AD5,Dex!$B$3:$N200,8,FALSE),"")} -> 45 | AF18: {=IFERROR(VLOOKUP(AE18,Dex!$P$22:$Q$276,2,FALSE),"")}
E19: ATK | F19: {=IFERROR(VLOOKUP(E5,Dex!$B$3:$N200,9,FALSE),"")} -> 72 | G19: {=IFERROR(VLOOKUP(F19,Dex!$P$22:$Q$276,2,FALSE),"")} | J19: ATK | K19: {=IFERROR(VLOOKUP(J5,Dex!$B$3:$N200,9,FALSE),"")} -> 85 | L19: {=IFERROR(VLOOKUP(K19,Dex!$P$22:$Q$276,2,FALSE),"")} | O19: ATK | P19: {=IFERROR(VLOOKUP(O5,Dex!$B$3:$N200,9,FALSE),"")} -> 55 | Q19: {=IFERROR(VLOOKUP(P19,Dex!$P$22:$Q$276,2,FALSE),"")} | T19: ATK | U19: {=IFERROR(VLOOKUP(T5,Dex!$B$3:$N200,9,FALSE),"")} -> 41 | V19: {=IFERROR(VLOOKUP(U19,Dex!$P$22:$Q$276,2,FALSE),"")} | Y19: ATK | Z19: {=IFERROR(VLOOKUP(Y5,Dex!$B$3:$N200,9,FALSE),"")} -> 112 | AA19: {=IFERROR(VLOOKUP(Z19,Dex!$P$22:$Q$276,2,FALSE),"")} | AD19: ATK | AE19: {=IFERROR(VLOOKUP(AD5,Dex!$B$3:$N200,9,FALSE),"")} -> 70 | AF19: {=IFERROR(VLOOKUP(AE19,Dex!$P$22:$Q$276,2,FALSE),"")}
E20: DEF | F20: {=IFERROR(VLOOKUP(E5,Dex!$B$3:$N200,10,FALSE),"")} -> 78 | G20: {=IFERROR(VLOOKUP(F20,Dex!$P$22:$Q$276,2,FALSE),"")} | J20: DEF | K20: {=IFERROR(VLOOKUP(J5,Dex!$B$3:$N200,10,FALSE),"")} -> 40 | L20: {=IFERROR(VLOOKUP(K20,Dex!$P$22:$Q$276,2,FALSE),"")} | O20: DEF | P20: {=IFERROR(VLOOKUP(O5,Dex!$B$3:$N200,10,FALSE),"")} -> 65 | Q20: {=IFERROR(VLOOKUP(P20,Dex!$P$22:$Q$276,2,FALSE),"")} | T20: DEF | U20: {=IFERROR(VLOOKUP(T5,Dex!$B$3:$N200,10,FALSE),"")} -> 77 | V20: {=IFERROR(VLOOKUP(U20,Dex!$P$22:$Q$276,2,FALSE),"")} | Y20: DEF | Z20: {=IFERROR(VLOOKUP(Y5,Dex!$B$3:$N200,10,FALSE),"")} -> 45 | AA20: {=IFERROR(VLOOKUP(Z20,Dex!$P$22:$Q$276,2,FALSE),"")} | AD20: DEF | AE20: {=IFERROR(VLOOKUP(AD5,Dex!$B$3:$N200,10,FALSE),"")} -> 63 | AF20: {=IFERROR(VLOOKUP(AE20,Dex!$P$22:$Q$276,2,FALSE),"")}
E21: SPA | F21: {=IFERROR(VLOOKUP(E5,Dex!$B$3:$N200,11,FALSE),"")} -> 38 | G21: {=IFERROR(VLOOKUP(F21,Dex!$P$22:$Q$276,2,FALSE),"")} | J21: SPA | K21: {=IFERROR(VLOOKUP(J5,Dex!$B$3:$N200,11,FALSE),"")} -> 85 | L21: {=IFERROR(VLOOKUP(K21,Dex!$P$22:$Q$276,2,FALSE),"")} | O21: SPA | P21: {=IFERROR(VLOOKUP(O5,Dex!$B$3:$N200,11,FALSE),"")} -> 105 | Q21: {=IFERROR(VLOOKUP(P21,Dex!$P$22:$Q$276,2,FALSE),"")} | T21: SPA | U21: {=IFERROR(VLOOKUP(T5,Dex!$B$3:$N200,11,FALSE),"")} -> 61 | V21: {=IFERROR(VLOOKUP(U21,Dex!$P$22:$Q$276,2,FALSE),"")} | Y21: SPA | Z21: {=IFERROR(VLOOKUP(Y5,Dex!$B$3:$N200,11,FALSE),"")} -> 74 | AA21: {=IFERROR(VLOOKUP(Z21,Dex!$P$22:$Q$276,2,FALSE),"")} | AD21: SPA | AE21: {=IFERROR(VLOOKUP(AD5,Dex!$B$3:$N200,11,FALSE),"")} -> 30 | AF21: {=IFERROR(VLOOKUP(AE21,Dex!$P$22:$Q$276,2,FALSE),"")}
E22: SPD | F22: {=IFERROR(VLOOKUP(E5,Dex!$B$3:$N200,12,FALSE),"")} -> 42 | G22: {=IFERROR(VLOOKUP(F22,Dex!$P$22:$Q$276,2,FALSE),"")} | J22: SPD | K22: {=IFERROR(VLOOKUP(J5,Dex!$B$3:$N200,12,FALSE),"")} -> 40 | L22: {=IFERROR(VLOOKUP(K22,Dex!$P$22:$Q$276,2,FALSE),"")} | O22: SPD | P22: {=IFERROR(VLOOKUP(O5,Dex!$B$3:$N200,12,FALSE),"")} -> 85 | Q22: {=IFERROR(VLOOKUP(P22,Dex!$P$22:$Q$276,2,FALSE),"")} | T22: SPD | U22: {=IFERROR(VLOOKUP(T5,Dex!$B$3:$N200,12,FALSE),"")} -> 87 | V22: {=IFERROR(VLOOKUP(U22,Dex!$P$22:$Q$276,2,FALSE),"")} | Y22: SPD | Z22: {=IFERROR(VLOOKUP(Y5,Dex!$B$3:$N200,12,FALSE),"")} -> 45 | AA22: {=IFERROR(VLOOKUP(Z22,Dex!$P$22:$Q$276,2,FALSE),"")} | AD22: SPD | AE22: {=IFERROR(VLOOKUP(AD5,Dex!$B$3:$N200,12,FALSE),"")} -> 45 | AF22: {=IFERROR(VLOOKUP(AE22,Dex!$P$22:$Q$276,2,FALSE),"")}
E23: SPE | F23: {=IFERROR(VLOOKUP(E5,Dex!$B$3:$N200,13,FALSE),"")} -> 32 | G23: {=IFERROR(VLOOKUP(F23,Dex!$P$22:$Q$276,2,FALSE),"")} | J23: SPE | K23: {=IFERROR(VLOOKUP(J5,Dex!$B$3:$N200,13,FALSE),"")} -> 35 | L23: {=IFERROR(VLOOKUP(K23,Dex!$P$22:$Q$276,2,FALSE),"")} | O23: SPE | P23: {=IFERROR(VLOOKUP(O5,Dex!$B$3:$N200,13,FALSE),"")} -> 90 | Q23: {=IFERROR(VLOOKUP(P23,Dex!$P$22:$Q$276,2,FALSE),"")} | T23: SPE | U23: {=IFERROR(VLOOKUP(T5,Dex!$B$3:$N200,13,FALSE),"")} -> 23 | V23: {=IFERROR(VLOOKUP(U23,Dex!$P$22:$Q$276,2,FALSE),"")} | Y23: SPE | Z23: {=IFERROR(VLOOKUP(Y5,Dex!$B$3:$N200,13,FALSE),"")} -> 70 | AA23: {=IFERROR(VLOOKUP(Z23,Dex!$P$22:$Q$276,2,FALSE),"")} | AD23: SPE | AE23: {=IFERROR(VLOOKUP(AD5,Dex!$B$3:$N200,13,FALSE),"")} -> 47 | AF23: {=IFERROR(VLOOKUP(AE23,Dex!$P$22:$Q$276,2,FALSE),"")}
E24: SPEED STAT: | H24: =ROUNDDOWN((ROUNDDOWN(((((2*F23+31)*E6)/100+5)),0))*1,0) -> 17 | J24: SPEED STAT: | M24: =ROUNDDOWN((ROUNDDOWN(((((2*K23+31)*J6)/100+5)),0))*1,0) -> 20 | O24: SPEED STAT: | R24: =ROUNDDOWN((ROUNDDOWN(((((2*P23+31)*O6)/100+5)),0))*1,0) -> 34 | T24: SPEED STAT: | W24: =ROUNDDOWN((ROUNDDOWN(((((2*U23+31)*T6)/100+5)),0))*1,0) -> 17 | Y24: SPEED STAT: | AB24: =ROUNDDOWN((ROUNDDOWN(((((2*Z23+31)*Y6)/100+5)),0))*1,0) -> 28 | AD24: SPEED STAT: | AG24: =ROUNDDOWN((ROUNDDOWN(((((2*AE23+0)*AD6)/100+5)),0))*1,0) -> 19
J25: SAND RUSH: | M25: =M24*2 -> 40
E28: BATTLE EFFECT: PERMANENT RAIN
C29: =IMAGE("https://i.ibb.co/mh2zYn4/Misty.png") | E29: {=IFERROR(VLOOKUP(E30,Dex!$B$3:$G200,3,FALSE),"")} | J29: {=IFERROR(VLOOKUP(J30,Dex!$B$3:$G200,3,FALSE),"")} | O29: {=IFERROR(VLOOKUP(O30,Dex!$B$3:$G200,3,FALSE),"")} | T29: {=IFERROR(VLOOKUP(T30,Dex!$B$3:$G200,3,FALSE),"")} | Y29: {=IFERROR(VLOOKUP(Y30,Dex!$B$3:$G200,3,FALSE),"")} | AD29: {=IFERROR(VLOOKUP(AD30,Dex!$B$3:$G200,3,FALSE),"")}
C30: GYM LEADER MISTY | E30: Politoed | J30: Ludicolo | O30: Mantine | T30: Clodsire | Y30: Starmie | AD30: Toxicroak
E31: 27 | J31: 28 | O31: 27 | T31: 28 | Y31: 28 | AD31: 27
F32: {=IFERROR(VLOOKUP(E30,Dex!$B$3:$H200,5,FALSE),"")} | K32: {=IFERROR(VLOOKUP(J30,Dex!$B$3:$H200,5,FALSE),"")} | L32: {=IFERROR(VLOOKUP(J30,Dex!$B$3:$H200,7,FALSE),"")} | P32: {=IFERROR(VLOOKUP(O30,Dex!$B$3:$H200,5,FALSE),"")} | Q32: {=IFERROR(VLOOKUP(O30,Dex!$B$3:$H200,7,FALSE),"")} | U32: {=IFERROR(VLOOKUP(T30,Dex!$B$3:$H200,5,FALSE),"")} | V32: {=IFERROR(VLOOKUP(T30,Dex!$B$3:$H200,7,FALSE),"")} | Z32: {=IFERROR(VLOOKUP(Y30,Dex!$B$3:$H200,5,FALSE),"")} | AA32: {=IFERROR(VLOOKUP(Y30,Dex!$B$3:$H200,7,FALSE),"")} | AE32: {=IFERROR(VLOOKUP(AD30,Dex!$B$3:$H200,5,FALSE),"")} | AF32: {=IFERROR(VLOOKUP(AD30,Dex!$B$3:$H200,7,FALSE),"")}
E34: Sassy | J34: Mild | O34: Modest | T34: Careful | Y34: Modest | AD34: Jolly
E35: Drizzle | J35: Swift Swim | O35: Swift Swim | T35: Water Absorb | Y35: Analytic | AD35: Dry Skin
E36: Iapapa Berry | H36: =IMAGE("https://raw.githubusercontent.com/msikma/pokesprite/master/items/berry/iapapa.png",3) | J36: Sitrus Berry | M36: =IMAGE("https://raw.githubusercontent.com/msikma/pokesprite/master/items/berry/sitrus.png",3) | O36: Wacan Berry | R36: =IMAGE("https://raw.githubusercontent.com/msikma/pokesprite/master/items/berry/wacan.png",3) | T36: Black Sludge | W36: =IMAGE("https://raw.githubusercontent.com/msikma/pokesprite/master/items/hold-item/black-sludge.png",3) | Y36: Mystic Water | AB36: =IMAGE("https://raw.githubusercontent.com/msikma/pokesprite/master/items/hold-item/mystic-water.png",3) | AD36: Life Orb | AG36: =IMAGE("https://raw.githubusercontent.com/msikma/pokesprite/master/items/hold-item/life-orb.png",3)
E37: Flip Turn | H37: =IMAGE("https://raw.githubusercontent.com/msikma/pokesprite/master/misc/types/gen8/water.png",4,20,20) | J37: Giga Drain | M37: =IMAGE("https://raw.githubusercontent.com/msikma/pokesprite/master/misc/types/gen8/grass.png",4,20,20) | O37: Scald | R37: =IMAGE("https://raw.githubusercontent.com/msikma/pokesprite/master/misc/types/gen8/water.png",4,20,20) | T37: Poison Jab | W37: =IMAGE("https://raw.githubusercontent.com/msikma/pokesprite/master/misc/types/gen8/poison.png",4,20,20) | Y37: Scald | AB37: =IMAGE("https://raw.githubusercontent.com/msikma/pokesprite/master/misc/types/gen8/water.png",4,20,20) | AD37: Swords Dance | AG37: =IMAGE("https://raw.githubusercontent.com/msikma/pokesprite/master/misc/types/gen8/normal.png",4,20,20)
E38: Scald | H38: =IMAGE("https://raw.githubusercontent.com/msikma/pokesprite/master/misc/types/gen8/water.png",4,20,20) | J38: Scald | M38: =IMAGE("https://raw.githubusercontent.com/msikma/pokesprite/master/misc/types/gen8/water.png",4,20,20) | O38: Hurricane | R38: =IMAGE("https://raw.githubusercontent.com/msikma/pokesprite/master/misc/types/gen8/flying.png",4,20,20) | T38: Bulldoze | W38: =IMAGE("https://raw.githubusercontent.com/msikma/pokesprite/master/misc/types/gen8/ground.png",4,20,20) | Y38: Thunderbolt | AB38: =IMAGE("https://raw.githubusercontent.com/msikma/pokesprite/master/misc/types/gen8/electric.png",4,20,20) | AD38: Drain Punch | AG38: =IMAGE("https://raw.githubusercontent.com/msikma/pokesprite/master/misc/types/gen8/fighting.png",4,20,20)
E39: Earthquake | H39: =IMAGE("https://raw.githubusercontent.com/msikma/pokesprite/master/misc/types/gen8/ground.png",4,20,20) | J39: Aurora Beam | M39: =IMAGE("https://raw.githubusercontent.com/msikma/pokesprite/master/misc/types/gen8/ice.png",4,20,20) | O39: Roost | R39: =IMAGE("https://raw.githubusercontent.com/msikma/pokesprite/master/misc/types/gen8/flying.png",4,20,20) | T39: Recover | W39: =IMAGE("https://raw.githubusercontent.com/msikma/pokesprite/master/misc/types/gen8/normal.png",4,20,20) | Y39: Psyshock | AB39: =IMAGE("https://raw.githubusercontent.com/msikma/pokesprite/master/misc/types/gen8/psychic.png",4,20,20) | AD39: Poison Jab | AG39: =IMAGE("https://raw.githubusercontent.com/msikma/pokesprite/master/misc/types/gen8/poison.png",4,20,20)
E40: Toxic | H40: =IMAGE("https://raw.githubusercontent.com/msikma/pokesprite/master/misc/types/gen8/poison.png",4,20,20) | J40: Thunder Punch | M40: =IMAGE("https://raw.githubusercontent.com/msikma/pokesprite/master/misc/types/gen8/electric.png",4,20,20) | O40: HP Grass | R40: =IMAGE("https://raw.githubusercontent.com/msikma/pokesprite/master/misc/types/gen8/grass.png",4,20,20) | T40: Toxic | W40: =IMAGE("https://raw.githubusercontent.com/msikma/pokesprite/master/misc/types/gen8/poison.png",4,20,20) | Y40: Aurora Beam | AB40: =IMAGE("https://raw.githubusercontent.com/msikma/pokesprite/master/misc/types/gen8/ice.png",4,20,20) | AD40: Sucker Punch | AG40: =IMAGE("https://raw.githubusercontent.com/msikma/pokesprite/master/misc/types/gen8/dark.png",4,20,20)
E42: BASE STATS | J42: BASE STATS | O42: BASE STATS | T42: BASE STATS | Y42: BASE STATS | AD42: BASE STATS
E43: HP | F43: {=IFERROR(VLOOKUP(E30,Dex!$B$3:$N200,8,FALSE),"")} -> 90 | G43: {=IFERROR(VLOOKUP(F43,Dex!$P$22:$Q$276,2,FALSE),"")} | J43: HP | K43: {=IFERROR(VLOOKUP(J30,Dex!$B$3:$N200,8,FALSE),"")} -> 80 | L43: {=IFERROR(VLOOKUP(K43,Dex!$P$22:$Q$276,2,FALSE),"")} | O43: HP | P43: {=IFERROR(VLOOKUP(O30,Dex!$B$3:$N200,8,FALSE),"")} -> 85 | Q43: {=IFERROR(VLOOKUP(P43,Dex!$P$22:$Q$276,2,FALSE),"")} | T43: HP | U43: {=IFERROR(VLOOKUP(T30,Dex!$B$3:$N200,8,FALSE),"")} -> 130 | V43: {=IFERROR(VLOOKUP(U43,Dex!$P$22:$Q$276,2,FALSE),"")} | Y43: HP | Z43: {=IFERROR(VLOOKUP(Y30,Dex!$B$3:$N200,8,FALSE),"")} -> 60 | AA43: {=IFERROR(VLOOKUP(Z43,Dex!$P$22:$Q$276,2,FALSE),"")} | AD43: HP | AE43: {=IFERROR(VLOOKUP(AD30,Dex!$B$3:$N200,8,FALSE),"")} -> 83 | AF43: {=IFERROR(VLOOKUP(AE43,Dex!$P$22:$Q$276,2,FALSE),"")}
E44: ATK | F44: {=IFERROR(VLOOKUP(E30,Dex!$B$3:$N200,9,FALSE),"")} -> 75 | G44: {=IFERROR(VLOOKUP(F44,Dex!$P$22:$Q$276,2,FALSE),"")} | J44: ATK | K44: {=IFERROR(VLOOKUP(J30,Dex!$B$3:$N200,9,FALSE),"")} -> 70 | L44: {=IFERROR(VLOOKUP(K44,Dex!$P$22:$Q$276,2,FALSE),"")} | O44: ATK | P44: {=IFERROR(VLOOKUP(O30,Dex!$B$3:$N200,9,FALSE),"")} -> 40 | Q44: {=IFERROR(VLOOKUP(P44,Dex!$P$22:$Q$276,2,FALSE),"")} | T44: ATK | U44: {=IFERROR(VLOOKUP(T30,Dex!$B$3:$N200,9,FALSE),"")} -> 75 | V44: {=IFERROR(VLOOKUP(U44,Dex!$P$22:$Q$276,2,FALSE),"")} | Y44: ATK | Z44: {=IFERROR(VLOOKUP(Y30,Dex!$B$3:$N200,9,FALSE),"")} -> 75 | AA44: {=IFERROR(VLOOKUP(Z44,Dex!$P$22:$Q$276,2,FALSE),"")} | AD44: ATK | AE44: {=IFERROR(VLOOKUP(AD30,Dex!$B$3:$N200,9,FALSE),"")} -> 106 | AF44: {=IFERROR(VLOOKUP(AE44,Dex!$P$22:$Q$276,2,FALSE),"")}
E45: DEF | F45: {=IFERROR(VLOOKUP(E30,Dex!$B$3:$N200,10,FALSE),"")} -> 75 | G45: {=IFERROR(VLOOKUP(F45,Dex!$P$22:$Q$276,2,FALSE),"")} | J45: DEF | K45: {=IFERROR(VLOOKUP(J30,Dex!$B$3:$N200,10,FALSE),"")} -> 70 | L45: {=IFERROR(VLOOKUP(K45,Dex!$P$22:$Q$276,2,FALSE),"")} | O45: DEF | P45: {=IFERROR(VLOOKUP(O30,Dex!$B$3:$N200,10,FALSE),"")} -> 70 | Q45: {=IFERROR(VLOOKUP(P45,Dex!$P$22:$Q$276,2,FALSE),"")} | T45: DEF | U45: {=IFERROR(VLOOKUP(T30,Dex!$B$3:$N200,10,FALSE),"")} -> 60 | V45: {=IFERROR(VLOOKUP(U45,Dex!$P$22:$Q$276,2,FALSE),"")} | Y45: DEF | Z45: {=IFERROR(VLOOKUP(Y30,Dex!$B$3:$N200,10,FALSE),"")} -> 85 | AA45: {=IFERROR(VLOOKUP(Z45,Dex!$P$22:$Q$276,2,FALSE),"")} | AD45: DEF | AE45: {=IFERROR(VLOOKUP(AD30,Dex!$B$3:$N200,10,FALSE),"")} -> 65 | AF45: {=IFERROR(VLOOKUP(AE45,Dex!$P$22:$Q$276,2,FALSE),"")}
E46: SPA | F46: {=IFERROR(VLOOKUP(E30,Dex!$B$3:$N200,11,FALSE),"")} -> 90 | G46: {=IFERROR(VLOOKUP(F46,Dex!$P$22:$Q$276,2,FALSE),"")} | J46: SPA | K46: {=IFERROR(VLOOKUP(J30,Dex!$B$3:$N200,11,FALSE),"")} -> 100 | L46: {=IFERROR(VLOOKUP(K46,Dex!$P$22:$Q$276,2,FALSE),"")} | O46: SPA | P46: {=IFERROR(VLOOKUP(O30,Dex!$B$3:$N200,11,FALSE),"")} -> 90 | Q46: {=IFERROR(VLOOKUP(P46,Dex!$P$22:$Q$276,2,FALSE),"")} | T46: SPA | U46: {=IFERROR(VLOOKUP(T30,Dex!$B$3:$N200,11,FALSE),"")} -> 45 | V46: {=IFERROR(VLOOKUP(U46,Dex!$P$22:$Q$276,2,FALSE),"")} | Y46: SPA | Z46: {=IFERROR(VLOOKUP(Y30,Dex!$B$3:$N200,11,FALSE),"")} -> 100 | AA46: {=IFERROR(VLOOKUP(Z46,Dex!$P$22:$Q$276,2,FALSE),"")} | AD46: SPA | AE46: {=IFERROR(VLOOKUP(AD30,Dex!$B$3:$N200,11,FALSE),"")} -> 86 | AF46: {=IFERROR(VLOOKUP(AE46,Dex!$P$22:$Q$276,2,FALSE),"")}
E47: SPD | F47: {=IFERROR(VLOOKUP(E30,Dex!$B$3:$N200,12,FALSE),"")} -> 100 | G47: {=IFERROR(VLOOKUP(F47,Dex!$P$22:$Q$276,2,FALSE),"")} | J47: SPD | K47: {=IFERROR(VLOOKUP(J30,Dex!$B$3:$N200,12,FALSE),"")} -> 100 | L47: {=IFERROR(VLOOKUP(K47,Dex!$P$22:$Q$276,2,FALSE),"")} | O47: SPD | P47: {=IFERROR(VLOOKUP(O30,Dex!$B$3:$N200,12,FALSE),"")} -> 140 | Q47: {=IFERROR(VLOOKUP(P47,Dex!$P$22:$Q$276,2,FALSE),"")} | T47: SPD | U47: {=IFERROR(VLOOKUP(T30,Dex!$B$3:$N200,12,FALSE),"")} -> 100 | V47: {=IFERROR(VLOOKUP(U47,Dex!$P$22:$Q$276,2,FALSE),"")} | Y47: SPD | Z47: {=IFERROR(VLOOKUP(Y30,Dex!$B$3:$N200,12,FALSE),"")} -> 85 | AA47: {=IFERROR(VLOOKUP(Z47,Dex!$P$22:$Q$276,2,FALSE),"")} | AD47: SPD | AE47: {=IFERROR(VLOOKUP(AD30,Dex!$B$3:$N200,12,FALSE),"")} -> 65 | AF47: {=IFERROR(VLOOKUP(AE47,Dex!$P$22:$Q$276,2,FALSE),"")}
E48: SPE | F48: {=IFERROR(VLOOKUP(E30,Dex!$B$3:$N200,13,FALSE),"")} -> 70 | G48: {=IFERROR(VLOOKUP(F48,Dex!$P$22:$Q$276,2,FALSE),"")} | J48: SPE | K48: {=IFERROR(VLOOKUP(J30,Dex!$B$3:$N200,13,FALSE),"")} -> 70 | L48: {=IFERROR(VLOOKUP(K48,Dex!$P$22:$Q$276,2,FALSE),"")} | O48: SPE | P48: {=IFERROR(VLOOKUP(O30,Dex!$B$3:$N200,13,FALSE),"")} -> 70 | Q48: {=IFERROR(VLOOKUP(P48,Dex!$P$22:$Q$276,2,FALSE),"")} | T48: SPE | U48: {=IFERROR(VLOOKUP(T30,Dex!$B$3:$N200,13,FALSE),"")} -> 20 | V48: {=IFERROR(VLOOKUP(U48,Dex!$P$22:$Q$276,2,FALSE),"")} | Y48: SPE | Z48: {=IFERROR(VLOOKUP(Y30,Dex!$B$3:$N200,13,FALSE),"")} -> 115 | AA48: {=IFERROR(VLOOKUP(Z48,Dex!$P$22:$Q$276,2,FALSE),"")} | AD48: SPE | AE48: {=IFERROR(VLOOKUP(AD30,Dex!$B$3:$N200,13,FALSE),"")} -> 85 | AF48: {=IFERROR(VLOOKUP(AE48,Dex!$P$22:$Q$276,2,FALSE),"")}
...

Sheet Kanto Rematch
E3: BATTLE EFFECT: PERMANENT SANDSTORM + SUPER EFFECTIVE MOVES DEAL 33% LESS TO BROCK
C4: =IMAGE("https://i.ibb.co/v10Rh61/Brock.png") | E4: {=IFERROR(VLOOKUP(E5,Dex!$B$3:$G101,3,FALSE),"")} | J4: {=IFERROR(VLOOKUP(J5,Dex!$B$3:$G101,3,FALSE),"")} | O4: {=IFERROR(VLOOKUP(O5,Dex!$B$3:$G101,3,FALSE),"")} | T4: {=IFERROR(VLOOKUP(T5,Dex!$B$3:$G101,3,FALSE),"")} | Y4: {=IFERROR(VLOOKUP(Y5,Dex!$B$3:$G101,3,FALSE),"")} | AD4: {=IFERROR(VLOOKUP(AD5,Dex!$B$3:$G101,3,FALSE),"")}
C5: GYM LEADER BROCK | E5: Iron Boulder | J5: Landorus-I | O5: Zygarde-C | T5: Iron Treads | Y5: Ursaluna-BM | AD5: Aerodactyl-Mega
E6: Highest Lv | J6: Highest Lv | O6: Highest Lv | T6: Highest Lv | Y6: Highest Lv | AD6: Highest Lv
F7: {=IFERROR(VLOOKUP(E5,Dex!$B$3:$H101,5,FALSE),"")} | G7: {=IFERROR(VLOOKUP(E5,Dex!$B$3:$H101,7,FALSE),"")} | K7: {=IFERROR(VLOOKUP(J5,Dex!$B$3:$H101,5,FALSE),"")} | L7: {=IFERROR(VLOOKUP(J5,Dex!$B$3:$H101,7,FALSE),"")} | P7: {=IFERROR(VLOOKUP(O5,Dex!$B$3:$H101,5,FALSE),"")} | Q7: {=IFERROR(VLOOKUP(O5,Dex!$B$3:$H101,7,FALSE),"")} | U7: {=IFERROR(VLOOKUP(T5,Dex!$B$3:$H101,5,FALSE),"")} | V7: {=IFERROR(VLOOKUP(T5,Dex!$B$3:$H101,7,FALSE),"")} | Z7: {=IFERROR(VLOOKUP(Y5,Dex!$B$3:$H101,5,FALSE),"")} | AA7: {=IFERROR(VLOOKUP(Y5,Dex!$B$3:$H101,7,FALSE),"")} | AE7: {=IFERROR(VLOOKUP(AD5,Dex!$B$3:$H101,5,FALSE),"")} | AF7: {=IFERROR(VLOOKUP(AD5,Dex!$B$3:$H101,7,FALSE),"")}
E9: Jolly | J9: Naive | O9: Careful | T9: Jolly | Y9: Modest | AD9: Jolly
E10: Quark Drive | J10: Sand Force | O10: Power Construct | T10: Quark Drive | Y10: Scrappy | AD10: Pressure Tough Claws (Mega)
E11: Lum Berry | H11: =IMAGE("https://raw.githubusercontent.com/msikma/pokesprite/master/items/berry/lum.png",3) | J11: Life Orb | M11: =IMAGE("https://raw.githubusercontent.com/msikma/pokesprite/master/items/hold-item/life-orb.png",3) | O11: Leftovers | R11: =IMAGE("https://raw.githubusercontent.com/msikma/pokesprite/master/items/hold-item/leftovers.png",3) | T11: Booster Energy | W11: =IMAGE("https://i.ibb.co/SK50ng3/booster.png",4,22,22) | Y11: Leftovers | AB11: =IMAGE("https://raw.githubusercontent.com/msikma/pokesprite/master/items/hold-item/leftovers.png",3) | AD11: Aerodactylite | AG11: =IMAGE("https://raw.githubusercontent.com/msikma/pokesprite/master/items/mega-stone/aerodactylite.png",3)
E12: Stealth Rock | H12: =IMAGE("https://raw.githubusercontent.com/msikma/pokesprite/master/misc/types/gen8/rock.png",4,20,20) | J12: U-Turn | M12: =IMAGE("https://raw.githubusercontent.com/msikma/pokesprite/master/misc/types/gen8/bug.png",4,20,20) | O12: Coil | R12: =IMAGE("https://raw.githubusercontent.com/msikma/pokesprite/master/misc/types/gen8/poison.png",4,20,20) | T12: Knock Off | W12: =IMAGE("https://raw.githubusercontent.com/msikma/pokesprite/master/misc/types/gen8/dark.png",4,20,20) | Y12: Blood Moon | AB12: =IMAGE("https://raw.githubusercontent.com/msikma/pokesprite/master/misc/types/gen8/normal.png",4,20,20) | AD12: Dragon Dance | AG12: =IMAGE("https://raw.githubusercontent.com/msikma/pokesprite/master/misc/types/gen8/dragon.png",4,20,20)
E13: Close Combat | H13: =IMAGE("https://raw.githubusercontent.com/msikma/pokesprite/master/misc/types/gen8/fighting.png",4,20,20) | J13: Earthquake | M13: =IMAGE("https://raw.githubusercontent.com/msikma/pokesprite/master/misc/types/gen8/ground.png",4,20,20) | O13: Thous. Arrows | R13: =IMAGE("https://raw.githubusercontent.com/msikma/pokesprite/master/misc/types/gen8/ground.png",4,20,20) | T13: Earthquake | W13: =IMAGE("https://raw.githubusercontent.com/msikma/pokesprite/master/misc/types/gen8/ground.png",4,20,20) | Y13: Earth Power | AB13: =IMAGE("https://raw.githubusercontent.com/msikma/pokesprite/master/misc/types/gen8/ground.png",4,20,20) | AD13: Stone Edge | AG13: =IMAGE("https://raw.githubusercontent.com/msikma/pokesprite/master/misc/types/gen8/rock.png",4,20,20)
E14: Mighty Cleave | H14: =IMAGE("https://raw.githubusercontent.com/msikma/pokesprite/master/misc/types/gen8/rock.png",4,20,20) | J14: Stone Edge | M14: =IMAGE("https://raw.githubusercontent.com/msikma/pokesprite/master/misc/types/gen8/rock.png",4,20,20) | O14: Rest | R14: =IMAGE("https://raw.githubusercontent.com/msikma/pokesprite/master/misc/types/gen8/psychic.png",4,20,20) | T14: Iron Head | W14: =IMAGE("https://raw.githubusercontent.com/msikma/pokesprite/master/misc/types/gen8/steel.png",4,20,20) | Y14: Vacuum Wave | AB14: =IMAGE("https://raw.githubusercontent.com/msikma/pokesprite/master/misc/types/gen8/fighting.png",4,20,20) | AD14: Earthquake | AG14: =IMAGE("https://raw.githubusercontent.com/msikma/pokesprite/master/misc/types/gen8/ground.png",4,20,20)
E15: Zen Headbutt | H15: =IMAGE("https://raw.githubusercontent.com/msikma/pokesprite/master/misc/types/gen8/psychic.png",4,20,20) | J15: Grass Knot | M15: =IMAGE("https://raw.githubusercontent.com/msikma/pokesprite/master/misc/types/gen8/grass.png",4,20,20) | O15: Sleep Talk | R15: =IMAGE("https://raw.githubusercontent.com/msikma/pokesprite/master/misc/types/gen8/normal.png",4,20,20) | T15: Ice Spinner | W15: =IMAGE("https://raw.githubusercontent.com/msikma/pokesprite/master/misc/types/gen8/ice.png",4,20,20) | Y15: Hyper Voice | AB15: =IMAGE("https://raw.githubusercontent.com/msikma/pokesprite/master/misc/types/gen8/normal.png",4,20,20) | AD15: Dual Wingbeat | AG15: =IMAGE("https://raw.githubusercontent.com/msikma/pokesprite/master/misc/types/gen8/flying.png",4,20,20)
E17: BASE STATS | J17: BASE STATS | O17: BASE STATS | T17: BASE STATS | Y17: BASE STATS | AD17: BASE STATS
E18: HP | F18: {=IFERROR(VLOOKUP(E5,Dex!$B$3:$N101,8,FALSE),"")} -> 90 | G18: {=IFERROR(VLOOKUP(F18,Dex!$P$22:$Q$276,2,FALSE),"")} | J18: HP | K18: {=IFERROR(VLOOKUP(J5,Dex!$B$3:$N101,8,FALSE),"")} -> 89 | L18: {=IFERROR(VLOOKUP(K18,Dex!$P$22:$Q$276,2,FALSE),"")} | O18: HP | P18: {=IFERROR(VLOOKUP(O5,Dex!$B$3:$N101,8,FALSE),"")} -> 216 | Q18: {=IFERROR(VLOOKUP(P18,Dex!$P$22:$Q$276,2,FALSE),"")} | T18: HP | U18: {=IFERROR(VLOOKUP(T5,Dex!$B$3:$N101,8,FALSE),"")} -> 90 | V18: {=IFERROR(VLOOKUP(U18,Dex!$P$22:$Q$276,2,FALSE),"")} | Y18: HP | Z18: {=IFERROR(VLOOKUP(Y5,Dex!$B$3:$N101,8,FALSE),"")} -> 113 | AA18: {=IFERROR(VLOOKUP(Z18,Dex!$P$22:$Q$276,2,FALSE),"")} | AD18: HP | AE18: {=IFERROR(VLOOKUP(AD5,Dex!$B$3:$N101,8,FALSE),"")} -> 80 | AF18: {=IFERROR(VLOOKUP(AE18,Dex!$P$22:$Q$276,2,FALSE),"")}
E19: ATK | F19: {=IFERROR(VLOOKUP(E5,Dex!$B$3:$N101,9,FALSE),"")} -> 120 | G19: {=IFERROR(VLOOKUP(F19,Dex!$P$22:$Q$276,2,FALSE),"")} | J19: ATK | K19: {=IFERROR(VLOOKUP(J5,Dex!$B$3:$N101,9,FALSE),"")} -> 125 | L19: {=IFERROR(VLOOKUP(K19,Dex!$P$22:$Q$276,2,FALSE),"")} | O19: ATK | P19: {=IFERROR(VLOOKUP(O5,Dex!$B$3:$N101,9,FALSE),"")} -> 100 | Q19: {=IFERROR(VLOOKUP(P19,Dex!$P$22:$Q$276,2,FALSE),"")} | T19: ATK | U19: {=IFERROR(VLOOKUP(T5,Dex!$B$3:$N101,9,FALSE),"")} -> 112 | V19: {=IFERROR(VLOOKUP(U19,Dex!$P$22:$Q$276,2,FALSE),"")} | Y19: ATK | Z19: {=IFERROR(VLOOKUP(Y5,Dex!$B$3:$N101,9,FALSE),"")} -> 70 | AA19: {=IFERROR(VLOOKUP(Z19,Dex!$P$22:$Q$276,2,FALSE),"")} | AD19: ATK | AE19: {=IFERROR(VLOOKUP(AD5,Dex!$B$3:$N101,9,FALSE),"")} -> 135 | AF19: {=IFERROR(VLOOKUP(AE19,Dex!$P$22:$Q$276,2,FALSE),"")}
E20: DEF | F20: {=IFERROR(VLOOKUP(E5,Dex!$B$3:$N101,10,FALSE),"")} -> 80 | G20: {=IFERROR(VLOOKUP(F20,Dex!$P$22:$Q$276,2,FALSE),"")} | J20: DEF | K20: {=IFERROR(VLOOKUP(J5,Dex!$B$3:$N101,10,FALSE),"")} -> 90 | L20: {=IFERROR(VLOOKUP(K20,Dex!$P$22:$Q$276,2,FALSE),"")} | O20: DEF | P20: {=IFERROR(VLOOKUP(O5,Dex!$B$3:$N101,10,FALSE),"")} -> 121 | Q20: {=IFERROR(VLOOKUP(P20,Dex!$P$22:$Q$276,2,FALSE),"")} | T20: DEF | U20: {=IFERROR(VLOOKUP(T5,Dex!$B$3:$N101,10,FALSE),"")} -> 120 | V20: {=IFERROR(VLOOKUP(U20,Dex!$P$22:$Q$276,2,FALSE),"")} | Y20: DEF | Z20: {=IFERROR(VLOOKUP(Y5,Dex!$B$3:$N101,10,FALSE),"")} -> 120 | AA20: {=IFERROR(VLOOKUP(Z20,Dex!$P$22:$Q$276,2,FALSE),"")} | AD20: DEF | AE20: {=IFERROR(VLOOKUP(AD5,Dex!$B$3:$N101,10,FALSE),"")} -> 85 | AF20: {=IFERROR(VLOOKUP(AE20,Dex!$P$22:$Q$276,2,FALSE),"")}
E21: SPA | F21: {=IFERROR(VLOOKUP(E5,Dex!$B$3:$N101,11,FALSE),"")} -> 68 | G21: {=IFERROR(VLOOKUP(F21,Dex!$P$22:$Q$276,2,FALSE),"")} | J21: SPA | K21: {=IFERROR(VLOOKUP(J5,Dex!$B$3:$N101,11,FALSE),"")} -> 115 | L21: {=IFERROR(VLOOKUP(K21,Dex!$P$22:$Q$276,2,FALSE),"")} | O21: SPA | P21: {=IFERROR(VLOOKUP(O5,Dex!$B$3:$N101,11,FALSE),"")} -> 91 | Q21: {=IFERROR(VLOOKUP(P21,Dex!$P$22:$Q$276,2,FALSE),"")} | T21: SPA | U21: {=IFERROR(VLOOKUP(T5,Dex!$B$3:$N101,11,FALSE),"")} -> 72 | V21: {=IFERROR(VLOOKUP(U21,Dex!$P$22:$Q$276,2,FALSE),"")} | Y21: SPA | Z21: {=IFERROR(VLOOKUP(Y5,Dex!$B$3:$N101,11,FALSE),"")} -> 135 | AA21: {=IFERROR(VLOOKUP(Z21,Dex!$P$22:$Q$276,2,FALSE),"")} | AD21: SPA | AE21: {=IFERROR(VLOOKUP(AD5,Dex!$B$3:$N101,11,FALSE),"")} -> 70 | AF21: {=IFERROR(VLOOKUP(AE21,Dex!$P$22:$Q$276,2,FALSE),"")}
E22: SPD | F22: {=IFERROR(VLOOKUP(E5,Dex!$B$3:$N101,12,FALSE),"")} -> 108 | G22: {=IFERROR(VLOOKUP(F22,Dex!$P$22:$Q$276,2,FALSE),"")} | J22: SPD | K22: {=IFERROR(VLOOKUP(J5,Dex!$B$3:$N101,12,FALSE),"")} -> 80 | L22: {=IFERROR(VLOOKUP(K22,Dex!$P$22:$Q$276,2,FALSE),"")} | O22: SPD | P22: {=IFERROR(VLOOKUP(O5,Dex!$B$3:$N101,12,FALSE),"")} -> 95 | Q22: {=IFERROR(VLOOKUP(P22,Dex!$P$22:$Q$276,2,FALSE),"")} | T22: SPD | U22: {=IFERROR(VLOOKUP(T5,Dex!$B$3:$N101,12,FALSE),"")} -> 70 | V22: {=IFERROR(VLOOKUP(U22,Dex!$P$22:$Q$276,2,FALSE),"")} | Y22: SPD | Z22: {=IFERROR(VLOOKUP(Y5,Dex!$B$3:$N101,12,FALSE),"")} -> 65 | AA22: {=IFERROR(VLOOKUP(Z22,Dex!$P$22:$Q$276,2,FALSE),"")} | AD22: SPD | AE22: {=IFERROR(VLOOKUP(AD5,Dex!$B$3:$N101,12,FALSE),"")} -> 95 | AF22: {=IFERROR(VLOOKUP(AE22,Dex!$P$22:$Q$276,2,FALSE),"")}
C23: IF YOU'RE | E23: SPE | F23: {=IFERROR(VLOOKUP(E5,Dex!$B$3:$N101,13,FALSE),"")} -> 124 | G23: {=IFERROR(VLOOKUP(F23,Dex!$P$22:$Q$276,2,FALSE),"")} | J23: SPE | K23: {=IFERROR(VLOOKUP(J5,Dex!$B$3:$N101,13,FALSE),"")} -> 101 | L23: {=IFERROR(VLOOKUP(K23,Dex!$P$22:$Q$276,2,FALSE),"")} | O23: SPE | P23: {=IFERROR(VLOOKUP(O5,Dex!$B$3:$N101,13,FALSE),"")} -> 85 | Q23: {=IFERROR(VLOOKUP(P23,Dex!$P$22:$Q$276,2,FALSE),"")} | T23: SPE | U23: {=IFERROR(VLOOKUP(T5,Dex!$B$3:$N101,13,FALSE),"")} -> 106 | V23: {=IFERROR(VLOOKUP(U23,Dex!$P$22:$Q$276,2,FALSE),"")} | Y23: SPE | Z23: {=IFERROR(VLOOKUP(Y5,Dex!$B$3:$N101,13,FALSE),"")} -> 52 | AA23: {=IFERROR(VLOOKUP(Z23,Dex!$P$22:$Q$276,2,FALSE),"")} | AD23: SPE | AE23: {=IFERROR(VLOOKUP(AD5,Dex!$B$3:$N101,13,FALSE),"")} -> 150 | AF23: {=IFERROR(VLOOKUP(AE23,Dex!$P$22:$Q$276,2,FALSE),"")}
C24: LEVEL 68 ->> | E24: SPEED STAT: | H24: =ROUNDDOWN((ROUNDDOWN(((((2*F23+31)*68)/100+5)),0))*1.1,0) -> 213 | J24: SPEED STAT: | M24: =ROUNDDOWN((ROUNDDOWN(((((2*K23+31)*68)/100+5)),0))*1.1,0) -> 179 | O24: SPEED STAT: | R24: =ROUNDDOWN((ROUNDDOWN(((((2*P23+31)*68)/100+5)),0))*1,0) -> 141 | T24: SPEED STAT: | W24: =ROUNDDOWN((ROUNDDOWN(((((2*U23+31)*68)/100+5)),0))*1.1,0) -> 187 | Y24: SPEED STAT: | AB24: =ROUNDDOWN((ROUNDDOWN(((((2*Z23+31)*68)/100+5)),0))*1,0) -> 96 | AD24: SPEED STAT: | AG24: =ROUNDDOWN((ROUNDDOWN(((((2*AE23+31)*68)/100+5)),0))*1.1,0) -> 253
E28: BATTLE EFFECT: PERMANENT RAIN + PALAFIN IS PRE-TRANSFORMED
C29: =IMAGE("https://i.ibb.co/mh2zYn4/Misty.png") | E29: {=IFERROR(VLOOKUP(E30,Dex!$B$3:$G101,3,FALSE),"")} | J29: {=IFERROR(VLOOKUP(J30,Dex!$B$3:$G101,3,FALSE),"")} | O29: {=IFERROR(VLOOKUP(O30,Dex!$B$3:$G101,3,FALSE),"")} | T29: {=IFERROR(VLOOKUP(T30,Dex!$B$3:$G101,3,FALSE),"")} | Y29: {=IFERROR(VLOOKUP(Y30,Dex!$B$3:$G101,3,FALSE),"")} | AD29: {=IFERROR(VLOOKUP(AD30,Dex!$B$3:$G101,3,FALSE),"")}
C30: GYM LEADER MISTY | E30: Iron Bundle | J30: Palafin-Hero | O30: Kingdra | T30: Archaludon | Y30: Thundurus-T | AD30: Gyarados-Mega
E31: Highest Lv | J31: Highest Lv | O31: Highest Lv | T31: Highest Lv | Y31: Highest Lv | AD31: Highest Lv
F32: {=IFERROR(VLOOKUP(E30,Dex!$B$3:$H101,5,FALSE),"")} | G32: {=IFERROR(VLOOKUP(E30,Dex!$B$3:$H101,7,FALSE),"")} | K32: {=IFERROR(VLOOKUP(J30,Dex!$B$3:$H101,5,FALSE),"")} | P32: {=IFERROR(VLOOKUP(O30,Dex!$B$3:$H101,5,FALSE),"")} | Q32: {=IFERROR(VLOOKUP(O30,Dex!$B$3:$H101,7,FALSE),"")} | U32: {=IFERROR(VLOOKUP(T30,Dex!$B$3:$H101,5,FALSE),"")} | V32: {=IFERROR(VLOOKUP(T30,Dex!$B$3:$H101,7,FALSE),"")} | Z32: {=IFERROR(VLOOKUP(Y30,Dex!$B$3:$H101,5,FALSE),"")} | AA32: {=IFERROR(VLOOKUP(Y30,Dex!$B$3:$H101,7,FALSE),"")} | AE32: {=IFERROR(VLOOKUP(AD30,Dex!$B$3:$H101,5,FALSE),"")} | AF32: {=IFERROR(VLOOKUP(AD30,Dex!$B$3:$H101,7,FALSE),"")}
E34: Timid | J34: Jolly | O34: Modest | T34: Calm | Y34: Timid | AD34: Jolly
E35: Quark Drive | J35: Mold Breaker | O35: Swift Swim | T35: Stamina | Y35: Volt Absorb | AD35: Intimidate Mold Breaker (Mega)
E36: Focus Sash | H36: =IMAGE("https://raw.githubusercontent.com/msikma/pokesprite/master/items/hold-item/focus-sash.png",3) | J36: Mystic Water | M36: =IMAGE("https://raw.githubusercontent.com/msikma/pokesprite/master/items/hold-item/mystic-water.png",3) | O36: Life Orb | R36: =IMAGE("https://raw.githubusercontent.com/msikma/pokesprite/master/items/hold-item/life-orb.png",3) | T36: Assault Vest | W36: =IMAGE("https://raw.githubusercontent.com/msikma/pokesprite/master/items/hold-item/assault-vest.png",3) | Y36: Fightinium Z | AB36: =IMAGE("https://raw.githubusercontent.com/msikma/pokesprite/master/items/z-crystals/fightinium-z--held.png",3) | AD36: Gyaradosite | AG36: =IMAGE("https://raw.githubusercontent.com/msikma/pokesprite/master/items/mega-stone/gyaradosite.png",3)
E37: Hydro Pump | H37: =IMAGE("https://raw.githubusercontent.com/msikma/pokesprite/master/misc/types/gen8/water.png",4,20,20) | J37: Jet Punch | M37: =IMAGE("https://raw.githubusercontent.com/msikma/pokesprite/master/misc/types/gen8/water.png",4,20,20) | O37: Hydro Pump | R37: =IMAGE("https://raw.githubusercontent.com/msikma/pokesprite/master/misc/types/gen8/water.png",4,20,20) | T37: Body Press | W37: =IMAGE("https://raw.githubusercontent.com/msikma/pokesprite/master/misc/types/gen8/fighting.png",4,20,20) | Y37: Nasty Plot | AB37: =IMAGE("https://raw.githubusercontent.com/msikma/pokesprite/master/misc/types/gen8/dark.png",4,20,20) | AD37: Dragon Dance | AG37: =IMAGE("https://raw.githubusercontent.com/msikma/pokesprite/master/misc/types/gen8/dragon.png",4,20,20)
E38: Freeze-Dry | H38: =IMAGE("https://raw.githubusercontent.com/msikma/pokesprite/master/misc/types/gen8/ice.png",4,20,20) | J38: Waterfall | M38: =IMAGE("https://raw.githubusercontent.com/msikma/pokesprite/master/misc/types/gen8/water.png",4,20,20) | O38: Draco Barrage | R38: =IMAGE("https://raw.githubusercontent.com/msikma/pokesprite/master/misc/types/gen8/dragon.png",4,20,20) | T38: Electro Shot | W38: =IMAGE("https://raw.githubusercontent.com/msikma/pokesprite/master/misc/types/gen8/electric.png",4,20,20) | Y38: Thunder | AB38: =IMAGE("https://raw.githubusercontent.com/msikma/pokesprite/master/misc/types/gen8/electric.png",4,20,20) | AD38: Waterfall | AG38: =IMAGE("https://raw.githubusercontent.com/msikma/pokesprite/master/misc/types/gen8/water.png",4,20,20)
E39: Flip Turn | H39: =IMAGE("https://raw.githubusercontent.com/msikma/pokesprite/master/misc/types/gen8/water.png",4,20,20) | J39: Drain Punch | M39: =IMAGE("https://raw.githubusercontent.com/msikma/pokesprite/master/misc/types/gen8/fighting.png",4,20,20) | O39: Hurricane | R39: =IMAGE("https://raw.githubusercontent.com/msikma/pokesprite/master/misc/types/gen8/flying.png",4,20,20) | T39: Dragon Pulse | W39: =IMAGE("https://raw.githubusercontent.com/msikma/pokesprite/master/misc/types/gen8/dragon.png",4,20,20) | Y39: Weather Ball | AB39: =IMAGE("https://raw.githubusercontent.com/msikma/pokesprite/master/misc/types/gen8/water.png",4,20,20) | AD39: Crunch | AG39: =IMAGE("https://raw.githubusercontent.com/msikma/pokesprite/master/misc/types/gen8/dark.png",4,20,20)
E40: Ice Beam | H40: =IMAGE("https://raw.githubusercontent.com/msikma/pokesprite/master/misc/types/gen8/ice.png",4,20,20) | J40: Bulk Up | M40: =IMAGE("https://raw.githubusercontent.com/msikma/pokesprite/master/misc/types/gen8/fighting.png",4,20,20) | O40: Flip Turn | R40: =IMAGE("https://raw.githubusercontent.com/msikma/pokesprite/master/misc/types/gen8/water.png",4,20,20) | T40: Flash Cannon | W40: =IMAGE("https://raw.githubusercontent.com/msikma/pokesprite/master/misc/types/gen8/steel.png",4,20,20) | Y40: Focus Blast | AB40: =IMAGE("https://raw.githubusercontent.com/msikma/pokesprite/master/misc/types/gen8/fighting.png",4,20,20) | AD40: Earthquake | AG40: =IMAGE("https://raw.githubusercontent.com/msikma/pokesprite/master/misc/types/gen8/ground.png",4,20,20)
E42: BASE STATS | J42: BASE STATS | O42: BASE STATS | T42: BASE STATS | Y42: BASE STATS | AD42: BASE STATS
E43: HP | F43: {=IFERROR(VLOOKUP(E30,Dex!$B$3:$N101,8,FALSE),"")} -> 56 | G43: {=IFERROR(VLOOKUP(F43,Dex!$P$22:$Q$276,2,FALSE),"")} | J43: HP | K43: {=IFERROR(VLOOKUP(J30,Dex!$B$3:$N101,8,FALSE),"")} -> 100 | L43: {=IFERROR(VLOOKUP(K43,Dex!$P$22:$Q$276,2,FALSE),"")} | O43: HP | P43: {=IFERROR(VLOOKUP(O30,Dex!$B$3:$N101,8,FALSE),"")} -> 75 | Q43: {=IFERROR(VLOOKUP(P43,Dex!$P$22:$Q$276,2,FALSE),"")} | T43: HP | U43: {=IFERROR(VLOOKUP(T30,Dex!$B$3:$N101,8,FALSE),"")} -> 90 | V43: {=IFERROR(VLOOKUP(U43,Dex!$P$22:$Q$276,2,FALSE),"")} | Y43: HP | Z43: {=IFERROR(VLOOKUP(Y30,Dex!$B$3:$N101,8,FALSE),"")} -> 79 | AA43: {=IFERROR(VLOOKUP(Z43,Dex!$P$22:$Q$276,2,FALSE),"")} | AD43: HP | AE43: {=IFERROR(VLOOKUP(AD30,Dex!$B$3:$N101,8,FALSE),"")} -> 95 | AF43: {=IFERROR(VLOOKUP(AE43,Dex!$P$22:$Q$276,2,FALSE),"")}
E44: ATK | F44: {=IFERROR(VLOOKUP(E30,Dex!$B$3:$N101,9,FALSE),"")} -> 80 | G44: {=IFERROR(VLOOKUP(F44,Dex!$P$22:$Q$276,2,FALSE),"")} | J44: ATK | K44: {=IFERROR(VLOOKUP(J30,Dex!$B$3:$N101,9,FALSE),"")} -> 160 | L44: {=IFERROR(VLOOKUP(K44,Dex!$P$22:$Q$276,2,FALSE),"")} | O44: ATK | P44: {=IFERROR(VLOOKUP(O30,Dex!$B$3:$N101,9,FALSE),"")} -> 95 | Q44: {=IFERROR(VLOOKUP(P44,Dex!$P$22:$Q$276,2,FALSE),"")} | T44: ATK | U44: {=IFERROR(VLOOKUP(T30,Dex!$B$3:$N101,9,FALSE),"")} -> 105 | V44: {=IFERROR(VLOOKUP(U44,Dex!$P$22:$Q$276,2,FALSE),"")} | Y44: ATK | Z44: {=IFERROR(VLOOKUP(Y30,Dex!$B$3:$N101,9,FALSE),"")} -> 105 | AA44: {=IFERROR(VLOOKUP(Z44,Dex!$P$22:$Q$276,2,FALSE),"")} | AD44: ATK | AE44: {=IFERROR(VLOOKUP(AD30,Dex!$B$3:$N101,9,FALSE),"")} -> 155 | AF44: {=IFERROR(VLOOKUP(AE44,Dex!$P$22:$Q$276,2,FALSE),"")}
E45: DEF | F45: {=IFERROR(VLOOKUP(E30,Dex!$B$3:$N101,10,FALSE),"")} -> 114 | G45: {=IFERROR(VLOOKUP(F45,Dex!$P$22:$Q$276,2,FALSE),"")} | J45: DEF | K45: {=IFERROR(VLOOKUP(J30,Dex!$B$3:$N101,10,FALSE),"")} -> 97 | L45: {=IFERROR(VLOOKUP(K45,Dex!$P$22:$Q$276,2,FALSE),"")} | O45: DEF | P45: {=IFERROR(VLOOKUP(O30,Dex!$B$3:$N101,10,FALSE),"")} -> 95 | Q45: {=IFERROR(VLOOKUP(P45,Dex!$P$22:$Q$276,2,FALSE),"")} | T45: DEF | U45: {=IFERROR(VLOOKUP(T30,Dex!$B$3:$N101,10,FALSE),"")} -> 130 | V45: {=IFERROR(VLOOKUP(U45,Dex!$P$22:$Q$276,2,FALSE),"")} | Y45: DEF | Z45: {=IFERROR(VLOOKUP(Y30,Dex!$B$3:$N101,10,FALSE),"")} -> 70 | AA45: {=IFERROR(VLOOKUP(Z45,Dex!$P$22:$Q$276,2,FALSE),"")} | AD45: DEF | AE45: {=IFERROR(VLOOKUP(AD30,Dex!$B$3:$N101,10,FALSE),"")} -> 109 | AF45: {=IFERROR(VLOOKUP(AE45,Dex!$P$22:$Q$276,2,FALSE),"")}
E46: SPA | F46: {=IFERROR(VLOOKUP(E30,Dex!$B$3:$N101,11,FALSE),"")} -> 124 | G46: {=IFERROR(VLOOKUP(F46,Dex!$P$22:$Q$276,2,FALSE),"")} | J46: SPA | K46: {=IFERROR(VLOOKUP(J30,Dex!$B$3:$N101,11,FALSE),"")} -> 106 | L46: {=IFERROR(VLOOKUP(K46,Dex!$P$22:$Q$276,2,FALSE),"")} | O46: SPA | P46: {=IFERROR(VLOOKUP(O30,Dex!$B$3:$N101,11,FALSE),"")} -> 95 | Q46: {=IFERROR(VLOOKUP(P46,Dex!$P$22:$Q$276,2,FALSE),"")} | T46: SPA | U46: {=IFERROR(VLOOKUP(T30,Dex!$B$3:$N101,11,FALSE),"")} -> 125 | V46: {=IFERROR(VLOOKUP(U46,Dex!$P$22:$Q$276,2,FALSE),"")} | Y46: SPA | Z46: {=IFERROR(VLOOKUP(Y30,Dex!$B$3:$N101,11,FALSE),"")} -> 145 | AA46: {=IFERROR(VLOOKUP(Z46,Dex!$P$22:$Q$276,2,FALSE),"")} | AD46: SPA | AE46: {=IFERROR(VLOOKUP(AD30,Dex!$B$3:$N101,11,FALSE),"")} -> 70 | AF46: {=IFERROR(VLOOKUP(AE46,Dex!$P$22:$Q$276,2,FALSE),"")}
E47: SPD | F47: {=IFERROR(VLOOKUP(E30,Dex!$B$3:$N101,12,FALSE),"")} -> 60 | G47: {=IFERROR(VLOOKUP(F47,Dex!$P$22:$Q$276,2,FALSE),"")} | J47: SPD | K47: {=IFERROR(VLOOKUP(J30,Dex!$B$3:$N101,12,FALSE),"")} -> 87 | L47: {=IFERROR(VLOOKUP(K47,Dex!$P$22:$Q$276,2,FALSE),"")} | O47: SPD | P47: {=IFERROR(VLOOKUP(O30,Dex!$B$3:$N101,12,FALSE),"")} -> 95 | Q47: {=IFERROR(VLOOKUP(P47,Dex!$P$22:$Q$276,2,FALSE),"")} | T47: SPD | U47: {=IFERROR(VLOOKUP(T30,Dex!$B$3:$N101,12,FALSE),"")} -> 65 | V47: {=IFERROR(VLOOKUP(U47,Dex!$P$22:$Q$276,2,FALSE),"")} | Y47: SPD | Z47: {=IFERROR(VLOOKUP(Y30,Dex!$B$3:$N101,12,FALSE),"")} -> 80 | AA47: {=IFERROR(VLOOKUP(Z47,Dex!$P$22:$Q$276,2,FALSE),"")} | AD47: SPD | AE47: {=IFERROR(VLOOKUP(AD30,Dex!$B$3:$N101,12,FALSE),"")} -> 130 | AF47: {=IFERROR(VLOOKUP(AE47,Dex!$P$22:$Q$276,2,FALSE),"")}
C48: IF YOU'RE | E48: SPE | F48: {=IFERROR(VLOOKUP(E30,Dex!$B$3:$N101,13,FALSE),"")} -> 136 | G48: {=IFERROR(VLOOKUP(F48,Dex!$P$22:$Q$276,2,FALSE),"")} | J48: SPE | K48: {=IFERROR(VLOOKUP(J30,Dex!$B$3:$N101,13,FALSE),"")} -> 100 | L48: {=IFERROR(VLOOKUP(K48,Dex!$P$22:$Q$276,2,FALSE),"")} | O48: SPE | P48: {=IFERROR(VLOOKUP(O30,Dex!$B$3:$N101,13,FALSE),"")} -> 85 | Q48: {=IFERROR(VLOOKUP(P48,Dex!$P$22:$Q$276,2,FALSE),"")} | T48: SPE | U48: {=IFERROR(VLOOKUP(T30,Dex!$B$3:$N101,13,FALSE),"")} -> 85 | V48: {=IFERROR(VLOOKUP(U48,Dex!$P$22:$Q$276,2,FALSE),"")} | Y48: SPE | Z48: {=IFERROR(VLOOKUP(Y30,Dex!$B$3:$N101,13,FALSE),"")} -> 101 | AA48: {=IFERROR(VLOOKUP(Z48,Dex!$P$22:$Q$276,2,FALSE),"")} | AD48: SPE | AE48: {=IFERROR(VLOOKUP(AD30,Dex!$B$3:$N101,13,FALSE),"")} -> 81 | AF48: {=IFERROR(VLOOKUP(AE48,Dex!$P$22:$Q$276,2,FALSE),"")}
C49: LEVEL 68 ->> | E49: SPEED STAT: | H49: =ROUNDDOWN((ROUNDDOWN(((((2*F48+31)*68)/100+5)),0))*1.1,0) -> 232 | J49: SPEED STAT: | M49: =ROUNDDOWN((ROUNDDOWN(((((2*K48+31)*68)/100+5)),0))*1.1,0) -> 178 | O49: SPEED STAT: | R49: =ROUNDDOWN((ROUNDDOWN(((((2*P48+31)*68)/100+5)),0))*1,0) -> 141 | T49: SPEED STAT: | W49: =ROUNDDOWN((ROUNDDOWN(((((2*U48+31)*68)/100+5)),0))*1,0) -> 141 | Y49: SPEED STAT: | AB49: =ROUNDDOWN((ROUNDDOWN(((((2*Z48+31)*68)/100+5)),0))*1.1,0) -> 179 | AD49: SPEED STAT: | AG49: =ROUNDDOWN((ROUNDDOWN(((((2*AE48+31)*68)/100+5)),0))*1.1,0) -> 149
...

Sheet Johto Leaders
C3: =IMAGE("https://i.ibb.co/gMdPsRL/Falkner.png") | E3: {=IFERROR(VLOOKUP(E4,Dex!$B$3:$G252,3,FALSE),"")} | J3: {=IFERROR(VLOOKUP(J4,Dex!$B$3:$G252,3,FALSE),"")} | O3: {=IFERROR(VLOOKUP(O4,Dex!$B$3:$G252,3,FALSE),"")} | T3: {=IFERROR(VLOOKUP(T4,Dex!$B$3:$G252,3,FALSE),"")} | Y3: {=IFERROR(VLOOKUP(Y4,Dex!$B$3:$G252,3,FALSE),"")}
C4: PEWTER MUSEUM LEADER FALKNER | E4: Trumbeak | J4: Wattrel | O4: Yanma | T4: Squawkabilly-G | Y4: Farfetch'd-G
E5: Highest Lv -2 | J5: Highest Lv | O5: Highest Lv -3 | T5: Highest Lv -2 | Y5: Highest Lv -2
F6: {=IFERROR(VLOOKUP(E4,Dex!$B$3:$H252,5,FALSE),"")} | G6: {=IFERROR(VLOOKUP(E4,Dex!$B$3:$H252,7,FALSE),"")} | K6: {=IFERROR(VLOOKUP(J4,Dex!$B$3:$H252,5,FALSE),"")} | L6: {=IFERROR(VLOOKUP(J4,Dex!$B$3:$H252,7,FALSE),"")} | P6: {=IFERROR(VLOOKUP(O4,Dex!$B$3:$H252,5,FALSE),"")} | Q6: {=IFERROR(VLOOKUP(O4,Dex!$B$3:$H252,7,FALSE),"")} | U6: {=IFERROR(VLOOKUP(T4,Dex!$B$3:$H252,5,FALSE),"")} | V6: {=IFERROR(VLOOKUP(T4,Dex!$B$3:$H252,7,FALSE),"")} | Z6: {=IFERROR(VLOOKUP(Y4,Dex!$B$3:$H252,5,FALSE),"")}
E8: Bashful | J8: Modest | O8: Bashful | T8: Bashful | Y8: Bashful
E9: Skill Link | J9: Volt Absorb | O9: Speed Boost | T9: Hustle | Y9: Scrappy
E10: Lum Berry | H10: =IMAGE("https://raw.githubusercontent.com/msikma/pokesprite/master/items/berry/lum.png",3) | J10: Berry Juice | M10: =IMAGE("https://raw.githubusercontent.com/msikma/pokesprite/master/items/medicine/berry-juice.png",3) | O10: Lum Berry | R10: =IMAGE("https://raw.githubusercontent.com/msikma/pokesprite/master/items/berry/lum.png",3) | T10: Muscle Band | W10: =IMAGE("https://raw.githubusercontent.com/msikma/pokesprite/master/items/hold-item/muscle-band.png",3) | Y10: Leek | AB10: =IMAGE("https://raw.githubusercontent.com/msikma/pokesprite/master/items/curry-ingredient/large-leek.png",3)
E11: Flame Charge | H11: =IMAGE("https://raw.githubusercontent.com/msikma/pokesprite/master/misc/types/gen8/fire.png",4,20,20) | J11: Volt Switch | M11: =IMAGE("https://raw.githubusercontent.com/msikma/pokesprite/master/misc/types/gen8/electric.png",4,20,20) | O11: Mega Drain | R11: =IMAGE("https://raw.githubusercontent.com/msikma/pokesprite/master/misc/types/gen8/grass.png",4,20,20) | T11: Aerial Ace | W11: =IMAGE("https://raw.githubusercontent.com/msikma/pokesprite/master/misc/types/gen8/flying.png",4,20,20) | Y11: Rock Smash | AB11: =IMAGE("https://raw.githubusercontent.com/msikma/pokesprite/master/misc/types/gen8/fighting.png",4,20,20)
E12: Pluck | H12: =IMAGE("https://raw.githubusercontent.com/msikma/pokesprite/master/misc/types/gen8/flying.png",4,20,20) | J12: Air Slash | M12: =IMAGE("https://raw.githubusercontent.com/msikma/pokesprite/master/misc/types/gen8/flying.png",4,20,20) | O12: Ancient Power | R12: =IMAGE("https://raw.githubusercontent.com/msikma/pokesprite/master/misc/types/gen8/rock.png",4,20,20) | T12: Quick Attack | W12: =IMAGE("https://raw.githubusercontent.com/msikma/pokesprite/master/misc/types/gen8/normal.png",4,20,20) | Y12: Slam | AB12: =IMAGE("https://raw.githubusercontent.com/msikma/pokesprite/master/misc/types/gen8/normal.png",4,20,20)
E13: Bullet Seed | H13: =IMAGE("https://raw.githubusercontent.com/msikma/pokesprite/master/misc/types/gen8/grass.png",4,20,20) | J13: HP Ground | M13: =IMAGE("https://raw.githubusercontent.com/msikma/pokesprite/master/misc/types/gen8/ground.png",4,20,20) | O13: HP Bug | R13: =IMAGE("https://raw.githubusercontent.com/msikma/pokesprite/master/misc/types/gen8/bug.png",4,20,20) | T13: Reversal | W13: =IMAGE("https://raw.githubusercontent.com/msikma/pokesprite/master/misc/types/gen8/fighting.png",4,20,20) | Y13: Brutal Swing | AB13: =IMAGE("https://raw.githubusercontent.com/msikma/pokesprite/master/misc/types/gen8/dark.png",4,20,20)
E14: Sleep Talk | H14: =IMAGE("https://raw.githubusercontent.com/msikma/pokesprite/master/misc/types/gen8/normal.png",4,20,20) | J14: Sleep Talk | M14: =IMAGE("https://raw.githubusercontent.com/msikma/pokesprite/master/misc/types/gen8/normal.png",4,20,20) | O14: Air Cutter | R14: =IMAGE("https://raw.githubusercontent.com/msikma/pokesprite/master/misc/types/gen8/flying.png",4,20,20) | T14: Parting Shot | W14: =IMAGE("https://raw.githubusercontent.com/msikma/pokesprite/master/misc/types/gen8/dark.png",4,20,20) | Y14: Roost | AB14: =IMAGE("https://raw.githubusercontent.com/msikma/pokesprite/master/misc/types/gen8/flying.png",4,20,20)
E16: BASE STATS | J16: BASE STATS | O16: BASE STATS | T16: BASE STATS | Y16: BASE STATS
E17: HP | F17: {=IFERROR(VLOOKUP(E4,Dex!$B$3:$N252,8,FALSE),"")} -> 55 | G17: {=IFERROR(VLOOKUP(F17,Dex!$P$22:$Q$276,2,FALSE),"")} | J17: HP | K17: {=IFERROR(VLOOKUP(J4,Dex!$B$3:$N252,8,FALSE),"")} -> 40 | L17: {=IFERROR(VLOOKUP(K17,Dex!$P$22:$Q$276,2,FALSE),"")} | O17: HP | P17: {=IFERROR(VLOOKUP(O4,Dex!$B$3:$N252,8,FALSE),"")} -> 65 | Q17: {=IFERROR(VLOOKUP(P17,Dex!$P$22:$Q$276,2,FALSE),"")} | T17: HP | U17: {=IFERROR(VLOOKUP(T4,Dex!$B$3:$N252,8,FALSE),"")} -> 82 | V17: {=IFERROR(VLOOKUP(U17,Dex!$P$22:$Q$276,2,FALSE),"")} | Y17: HP | Z17: {=IFERROR(VLOOKUP(Y4,Dex!$B$3:$N252,8,FALSE),"")} -> 52 | AA17: {=IFERROR(VLOOKUP(Z17,Dex!$P$22:$Q$276,2,FALSE),"")}
E18: ATK | F18: {=IFERROR(VLOOKUP(E4,Dex!$B$3:$N252,9,FALSE),"")} -> 85 | G18: {=IFERROR(VLOOKUP(F18,Dex!$P$22:$Q$276,2,FALSE),"")} | J18: ATK | K18: {=IFERROR(VLOOKUP(J4,Dex!$B$3:$N252,9,FALSE),"")} -> 40 | L18: {=IFERROR(VLOOKUP(K18,Dex!$P$22:$Q$276,2,FALSE),"")} | O18: ATK | P18: {=IFERROR(VLOOKUP(O4,Dex!$B$3:$N252,9,FALSE),"")} -> 65 | Q18: {=IFERROR(VLOOKUP(P18,Dex!$P$22:$Q$276,2,FALSE),"")} | T18: ATK | U18: {=IFERROR(VLOOKUP(T4,Dex!$B$3:$N252,9,FALSE),"")} -> 96 | V18: {=IFERROR(VLOOKUP(U18,Dex!$P$22:$Q$276,2,FALSE),"")} | Y18: ATK | Z18: {=IFERROR(VLOOKUP(Y4,Dex!$B$3:$N252,9,FALSE),"")} -> 95 | AA18: {=IFERROR(VLOOKUP(Z18,Dex!$P$22:$Q$276,2,FALSE),"")}
E19: DEF | F19: {=IFERROR(VLOOKUP(E4,Dex!$B$3:$N252,10,FALSE),"")} -> 50 | G19: {=IFERROR(VLOOKUP(F19,Dex!$P$22:$Q$276,2,FALSE),"")} | J19: DEF | K19: {=IFERROR(VLOOKUP(J4,Dex!$B$3:$N252,10,FALSE),"")} -> 35 | L19: {=IFERROR(VLOOKUP(K19,Dex!$P$22:$Q$276,2,FALSE),"")} | O19: DEF | P19: {=IFERROR(VLOOKUP(O4,Dex!$B$3:$N252,10,FALSE),"")} -> 45 | Q19: {=IFERROR(VLOOKUP(P19,Dex!$P$22:$Q$276,2,FALSE),"")} | T19: DEF | U19: {=IFERROR(VLOOKUP(T4,Dex!$B$3:$N252,10,FALSE),"")} -> 51 | V19: {=IFERROR(VLOOKUP(U19,Dex!$P$22:$Q$276,2,FALSE),"")} | Y19: DEF | Z19: {=IFERROR(VLOOKUP(Y4,Dex!$B$3:$N252,10,FALSE),"")} -> 55 | AA19: {=IFERROR(VLOOKUP(Z19,Dex!$P$22:$Q$276,2,FALSE),"")}
E20: SPA | F20: {=IFERROR(VLOOKUP(E4,Dex!$B$3:$N252,11,FALSE),"")} -> 40 | G20: {=IFERROR(VLOOKUP(F20,Dex!$P$22:$Q$276,2,FALSE),"")} | J20: SPA | K20: {=IFERROR(VLOOKUP(J4,Dex!$B$3:$N252,11,FALSE),"")} -> 55 | L20: {=IFERROR(VLOOKUP(K20,Dex!$P$22:$Q$276,2,FALSE),"")} | O20: SPA | P20: {=IFERROR(VLOOKUP(O4,Dex!$B$3:$N252,11,FALSE),"")} -> 75 | Q20: {=IFERROR(VLOOKUP(P20,Dex!$P$22:$Q$276,2,FALSE),"")} | T20: SPA | U20: {=IFERROR(VLOOKUP(T4,Dex!$B$3:$N252,11,FALSE),"")} -> 45 | V20: {=IFERROR(VLOOKUP(U20,Dex!$P$22:$Q$276,2,FALSE),"")} | Y20: SPA | Z20: {=IFERROR(VLOOKUP(Y4,Dex!$B$3:$N252,11,FALSE),"")} -> 58 | AA20: {=IFERROR(VLOOKUP(Z20,Dex!$P$22:$Q$276,2,FALSE),"")}
E21: SPD | F21: {=IFERROR(VLOOKUP(E4,Dex!$B$3:$N252,12,FALSE),"")} -> 50 | G21: {=IFERROR(VLOOKUP(F21,Dex!$P$22:$Q$276,2,FALSE),"")} | J21: SPD | K21: {=IFERROR(VLOOKUP(J4,Dex!$B$3:$N252,12,FALSE),"")} -> 40 | L21: {=IFERROR(VLOOKUP(K21,Dex!$P$22:$Q$276,2,FALSE),"")} | O21: SPD | P21: {=IFERROR(VLOOKUP(O4,Dex!$B$3:$N252,12,FALSE),"")} -> 45 | Q21: {=IFERROR(VLOOKUP(P21,Dex!$P$22:$Q$276,2,FALSE),"")} | T21: SPD | U21: {=IFERROR(VLOOKUP(T4,Dex!$B$3:$N252,12,FALSE),"")} -> 51 | V21: {=IFERROR(VLOOKUP(U21,Dex!$P$22:$Q$276,2,FALSE),"")} | Y21: SPD | Z21: {=IFERROR(VLOOKUP(Y4,Dex!$B$3:$N252,12,FALSE),"")} -> 62 | AA21: {=IFERROR(VLOOKUP(Z21,Dex!$P$22:$Q$276,2,FALSE),"")}
C22: IF YOU'RE | E22: SPE | F22: {=IFERROR(VLOOKUP(E4,Dex!$B$3:$N252,13,FALSE),"")} -> 75 | G22: {=IFERROR(VLOOKUP(F22,Dex!$P$22:$Q$276,2,FALSE),"")} | J22: SPE | K22: {=IFERROR(VLOOKUP(J4,Dex!$B$3:$N252,13,FALSE),"")} -> 70 | L22: {=IFERROR(VLOOKUP(K22,Dex!$P$22:$Q$276,2,FALSE),"")} | O22: SPE | P22: {=IFERROR(VLOOKUP(O4,Dex!$B$3:$N252,13,FALSE),"")} -> 95 | Q22: {=IFERROR(VLOOKUP(P22,Dex!$P$22:$Q$276,2,FALSE),"")} | T22: SPE | U22: {=IFERROR(VLOOKUP(T4,Dex!$B$3:$N252,13,FALSE),"")} -> 92 | V22: {=IFERROR(VLOOKUP(U22,Dex!$P$22:$Q$276,2,FALSE),"")} | Y22: SPE | Z22: {=IFERROR(VLOOKUP(Y4,Dex!$B$3:$N252,13,FALSE),"")} -> 55 | AA22: {=IFERROR(VLOOKUP(Z22,Dex!$P$22:$Q$276,2,FALSE),"")}
C23: LEVEL 16 ->> | E23: SPEED STAT: | H23: =ROUNDDOWN((ROUNDDOWN(((((2*F22+31)*14)/100+5)),0))*1,0) -> 30 | J23: SPEED STAT: | M23: =ROUNDDOWN((ROUNDDOWN(((((2*K22+31)*16)/100+5)),0))*1,0) -> 32 | O23: SPEED STAT: | R23: =ROUNDDOWN((ROUNDDOWN(((((2*P22+31)*13)/100+5)),0))*1,0) -> 33 | T23: SPEED STAT: | W23: =ROUNDDOWN((ROUNDDOWN(((((2*U22+31)*14)/100+5)),0))*1,0) -> 35 | Y23: SPEED STAT: | AB23: =ROUNDDOWN((ROUNDDOWN(((((2*Z22+31)*14)/100+5)),0))*1,0) -> 24
O24: 1 S. BOOST: | R24: =ROUNDDOWN(R23*1.5,0) -> 49 | Y24: LEEK: | AB24: =ROUNDDOWN(AB23*1.5,0) -> 36
E27: (!) PRE LT. SURGE
E29: BATTLE EFFECT: PERMANENT RAIN
C30: =IMAGE("https://i.ibb.co/Lrh0bjy/Bugsy.png") | E30: {=IFERROR(VLOOKUP(E31,Dex!$B$3:$G252,3,FALSE),"")} | J30: {=IFERROR(VLOOKUP(J31,Dex!$B$3:$G252,3,FALSE),"")} | O30: {=IFERROR(VLOOKUP(O31,Dex!$B$3:$G252,3,FALSE),"")} | T30: {=IFERROR(VLOOKUP(T31,Dex!$B$3:$G252,3,FALSE),"")} | Y30: {=IFERROR(VLOOKUP(Y31,Dex!$B$3:$G252,3,FALSE),"")} | AD30: {=IFERROR(VLOOKUP(AD31,Dex!$B$3:$G252,3,FALSE),"")}
C31: ROUTE 25 LEADER BUGSY | E31: Kleavor | J31: Scizor | O31: Scyther | T31: Lokix | Y31: Araquanid | AD31: Vikavolt
E32: Highest Lv | J32: Highest Lv | O32: Highest Lv | T32: Highest Lv | Y32: Highest Lv | AD32: Highest Lv
F33: {=IFERROR(VLOOKUP(E31,Dex!$B$3:$H252,5,FALSE),"")} | G33: {=IFERROR(VLOOKUP(E31,Dex!$B$3:$H252,7,FALSE),"")} | K33: {=IFERROR(VLOOKUP(J31,Dex!$B$3:$H252,5,FALSE),"")} | L33: {=IFERROR(VLOOKUP(J31,Dex!$B$3:$H252,7,FALSE),"")} | P33: {=IFERROR(VLOOKUP(O31,Dex!$B$3:$H252,5,FALSE),"")} | Q33: {=IFERROR(VLOOKUP(O31,Dex!$B$3:$H252,7,FALSE),"")} | U33: {=IFERROR(VLOOKUP(T31,Dex!$B$3:$H252,5,FALSE),"")} | V33: {=IFERROR(VLOOKUP(T31,Dex!$B$3:$H252,7,FALSE),"")} | Z33: {=IFERROR(VLOOKUP(Y31,Dex!$B$3:$H252,5,FALSE),"")} | AA33: {=IFERROR(VLOOKUP(Y31,Dex!$B$3:$H252,7,FALSE),"")} | AE33: {=IFERROR(VLOOKUP(AD31,Dex!$B$3:$H252,5,FALSE),"")} | AF33: {=IFERROR(VLOOKUP(AD31,Dex!$B$3:$H252,7,FALSE),"")}
E35: Jolly | J35: Careful | O35: Adamant | T35: Jolly | Y35: Impish | AD35: Modest
E36: Sharpness | J36: Technician | O36: Technician | T36: Tinted Lens | Y36: Water Bubble | AD36: Levitate
E37: Focus Sash | H37: =IMAGE("https://raw.githubusercontent.com/msikma/pokesprite/master/items/hold-item/focus-sash.png",3) | J37: Assault Vest | M37: =IMAGE("https://raw.githubusercontent.com/msikma/pokesprite/master/items/hold-item/assault-vest.png",3) | O37: Muscle Band | R37: =IMAGE("https://raw.githubusercontent.com/msikma/pokesprite/master/items/hold-item/muscle-band.png",3) | T37: Silver Powder | W37: =IMAGE("https://raw.githubusercontent.com/msikma/pokesprite/master/items/hold-item/silver-powder.png",3) | Y37: Leftovers | AB37: =IMAGE("https://raw.githubusercontent.com/msikma/pokesprite/master/items/hold-item/leftovers.png",3) | AD37: Magnet | AG37: =IMAGE("https://raw.githubusercontent.com/msikma/pokesprite/master/items/hold-item/magnet.png",3)
E38: X-Scissor | H38: =IMAGE("https://raw.githubusercontent.com/msikma/pokesprite/master/misc/types/gen8/bug.png",4,20,20) | J38: Bullet Punch | M38: =IMAGE("https://raw.githubusercontent.com/msikma/pokesprite/master/misc/types/gen8/steel.png",4,20,20) | O38: Swords Dance | R38: =IMAGE("https://raw.githubusercontent.com/msikma/pokesprite/master/misc/types/gen8/normal.png",4,20,20) | T38: U-Turn | W38: =IMAGE("https://raw.githubusercontent.com/msikma/pokesprite/master/misc/types/gen8/bug.png",4,20,20) | Y38: Bug Bite | AB38: =IMAGE("https://raw.githubusercontent.com/msikma/pokesprite/master/misc/types/gen8/bug.png",4,20,20) | AD38: Volt Switch | AG38: =IMAGE("https://raw.githubusercontent.com/msikma/pokesprite/master/misc/types/gen8/electric.png",4,20,20)
